Workbook
Name _: #N/A
Name _______________________________FR1: {"Lpor",#N/A,FALSE,"Porta";"LRDOS1",#N/A,FALSE,"Rdos";"LRDOS2",#N/A,FALSE,"Rdos";"LBAL1",#N/A,FALSE,"Bala";"LTES1",#N/A,FALSE,"Teso"}
Name _______________________________FR1: {"Lpor",#N/A,FALSE,"Porta";"LRDOS1",#N/A,FALSE,"Rdos";"LRDOS2",#N/A,FALSE,"Rdos";"LBAL1",#N/A,FALSE,"Bala";"LTES1",#N/A,FALSE,"Teso"}
Name ______________________________FR1: {"Lpor",#N/A,FALSE,"Porta";"LRDOS1",#N/A,FALSE,"Rdos";"LRDOS2",#N/A,FALSE,"Rdos";"LBAL1",#N/A,FALSE,"Bala";"LTES1",#N/A,FALSE,"Teso"}
Name ______________________________FR1: {"Lpor",#N/A,FALSE,"Porta";"LRDOS1",#N/A,FALSE,"Rdos";"LRDOS2",#N/A,FALSE,"Rdos";"LBAL1",#N/A,FALSE,"Bala";"LTES1",#N/A,FALSE,"Teso"}
Name _____________________________FR1: {"Lpor",#N/A,FALSE,"Porta";"LRDOS1",#N/A,FALSE,"Rdos";"LRDOS2",#N/A,FALSE,"Rdos";"LBAL1",#N/A,FALSE,"Bala";"LTES1",#N/A,FALSE,"Teso"}
Name _____________________________FR1: {"Lpor",#N/A,FALSE,"Porta";"LRDOS1",#N/A,FALSE,"Rdos";"LRDOS2",#N/A,FALSE,"Rdos";"LBAL1",#N/A,FALSE,"Bala";"LTES1",#N/A,FALSE,"Teso"}
Name ____________________________FR1: {"Lpor",#N/A,FALSE,"Porta";"LRDOS1",#N/A,FALSE,"Rdos";"LRDOS2",#N/A,FALSE,"Rdos";"LBAL1",#N/A,FALSE,"Bala";"LTES1",#N/A,FALSE,"Teso"}
Name ____________________________FR1: {"Lpor",#N/A,FALSE,"Porta";"LRDOS1",#N/A,FALSE,"Rdos";"LRDOS2",#N/A,FALSE,"Rdos";"LBAL1",#N/A,FALSE,"Bala";"LTES1",#N/A,FALSE,"Teso"}
Name ___________________________FR1: {"Lpor",#N/A,FALSE,"Porta";"LRDOS1",#N/A,FALSE,"Rdos";"LRDOS2",#N/A,FALSE,"Rdos";"LBAL1",#N/A,FALSE,"Bala";"LTES1",#N/A,FALSE,"Teso"}
Name ___________________________FR1: {"Lpor",#N/A,FALSE,"Porta";"LRDOS1",#N/A,FALSE,"Rdos";"LRDOS2",#N/A,FALSE,"Rdos";"LBAL1",#N/A,FALSE,"Bala";"LTES1",#N/A,FALSE,"Teso"}
Name _________________________FR1: {"Lpor",#N/A,FALSE,"Porta";"LRDOS1",#N/A,FALSE,"Rdos";"LRDOS2",#N/A,FALSE,"Rdos";"LBAL1",#N/A,FALSE,"Bala";"LTES1",#N/A,FALSE,"Teso"}
Name _________________________FR1: {"Lpor",#N/A,FALSE,"Porta";"LRDOS1",#N/A,FALSE,"Rdos";"LRDOS2",#N/A,FALSE,"Rdos";"LBAL1",#N/A,FALSE,"Bala";"LTES1",#N/A,FALSE,"Teso"}
Name ________________________FR1: {"Lpor",#N/A,FALSE,"Porta";"LRDOS1",#N/A,FALSE,"Rdos";"LRDOS2",#N/A,FALSE,"Rdos";"LBAL1",#N/A,FALSE,"Bala";"LTES1",#N/A,FALSE,"Teso"}
Name ________________________FR1: {"Lpor",#N/A,FALSE,"Porta";"LRDOS1",#N/A,FALSE,"Rdos";"LRDOS2",#N/A,FALSE,"Rdos";"LBAL1",#N/A,FALSE,"Bala";"LTES1",#N/A,FALSE,"Teso"}
Name _______________________FR1: {"Lpor",#N/A,FALSE,"Porta";"LRDOS1",#N/A,FALSE,"Rdos";"LRDOS2",#N/A,FALSE,"Rdos";"LBAL1",#N/A,FALSE,"Bala";"LTES1",#N/A,FALSE,"Teso"}
Name _______________________FR1: {"Lpor",#N/A,FALSE,"Porta";"LRDOS1",#N/A,FALSE,"Rdos";"LRDOS2",#N/A,FALSE,"Rdos";"LBAL1",#N/A,FALSE,"Bala";"LTES1",#N/A,FALSE,"Teso"}
Name ______________________FR1: {"Lpor",#N/A,FALSE,"Porta";"LRDOS1",#N/A,FALSE,"Rdos";"LRDOS2",#N/A,FALSE,"Rdos";"LBAL1",#N/A,FALSE,"Bala";"LTES1",#N/A,FALSE,"Teso"}
Name ______________________FR1: {"Lpor",#N/A,FALSE,"Porta";"LRDOS1",#N/A,FALSE,"Rdos";"LRDOS2",#N/A,FALSE,"Rdos";"LBAL1",#N/A,FALSE,"Bala";"LTES1",#N/A,FALSE,"Teso"}
Name _____________________FR1: {"Lpor",#N/A,FALSE,"Porta";"LRDOS1",#N/A,FALSE,"Rdos";"LRDOS2",#N/A,FALSE,"Rdos";"LBAL1",#N/A,FALSE,"Bala";"LTES1",#N/A,FALSE,"Teso"}
Name _____________________FR1: {"Lpor",#N/A,FALSE,"Porta";"LRDOS1",#N/A,FALSE,"Rdos";"LRDOS2",#N/A,FALSE,"Rdos";"LBAL1",#N/A,FALSE,"Bala";"LTES1",#N/A,FALSE,"Teso"}
Name ____________________FR1: {"Lpor",#N/A,FALSE,"Porta";"LRDOS1",#N/A,FALSE,"Rdos";"LRDOS2",#N/A,FALSE,"Rdos";"LBAL1",#N/A,FALSE,"Bala";"LTES1",#N/A,FALSE,"Teso"}
Name ____________________FR1: {"Lpor",#N/A,FALSE,"Porta";"LRDOS1",#N/A,FALSE,"Rdos";"LRDOS2",#N/A,FALSE,"Rdos";"LBAL1",#N/A,FALSE,"Bala";"LTES1",#N/A,FALSE,"Teso"}
Name ___________________FR1: {"Lpor",#N/A,FALSE,"Porta";"LRDOS1",#N/A,FALSE,"Rdos";"LRDOS2",#N/A,FALSE,"Rdos";"LBAL1",#N/A,FALSE,"Bala";"LTES1",#N/A,FALSE,"Teso"}
Name ___________________FR1: {"Lpor",#N/A,FALSE,"Porta";"LRDOS1",#N/A,FALSE,"Rdos";"LRDOS2",#N/A,FALSE,"Rdos";"LBAL1",#N/A,FALSE,"Bala";"LTES1",#N/A,FALSE,"Teso"}
Name __________________FR1: {"Lpor",#N/A,FALSE,"Porta";"LRDOS1",#N/A,FALSE,"Rdos";"LRDOS2",#N/A,FALSE,"Rdos";"LBAL1",#N/A,FALSE,"Bala";"LTES1",#N/A,FALSE,"Teso"}
Name __________________FR1: {"Lpor",#N/A,FALSE,"Porta";"LRDOS1",#N/A,FALSE,"Rdos";"LRDOS2",#N/A,FALSE,"Rdos";"LBAL1",#N/A,FALSE,"Bala";"LTES1",#N/A,FALSE,"Teso"}
Name _________________FR1: {"Lpor",#N/A,FALSE,"Porta";"LRDOS1",#N/A,FALSE,"Rdos";"LRDOS2",#N/A,FALSE,"Rdos";"LBAL1",#N/A,FALSE,"Bala";"LTES1",#N/A,FALSE,"Teso"}
Name _________________FR1: {"Lpor",#N/A,FALSE,"Porta";"LRDOS1",#N/A,FALSE,"Rdos";"LRDOS2",#N/A,FALSE,"Rdos";"LBAL1",#N/A,FALSE,"Bala";"LTES1",#N/A,FALSE,"Teso"}
Name ________________FR1: {"Lpor",#N/A,FALSE,"Porta";"LRDOS1",#N/A,FALSE,"Rdos";"LRDOS2",#N/A,FALSE,"Rdos";"LBAL1",#N/A,FALSE,"Bala";"LTES1",#N/A,FALSE,"Teso"}
Name ________________FR1: {"Lpor",#N/A,FALSE,"Porta";"LRDOS1",#N/A,FALSE,"Rdos";"LRDOS2",#N/A,FALSE,"Rdos";"LBAL1",#N/A,FALSE,"Bala";"LTES1",#N/A,FALSE,"Teso"}
Name _______________FR1: {"Lpor",#N/A,FALSE,"Porta";"LRDOS1",#N/A,FALSE,"Rdos";"LRDOS2",#N/A,FALSE,"Rdos";"LBAL1",#N/A,FALSE,"Bala";"LTES1",#N/A,FALSE,"Teso"}
Name _______________FR1: {"Lpor",#N/A,FALSE,"Porta";"LRDOS1",#N/A,FALSE,"Rdos";"LRDOS2",#N/A,FALSE,"Rdos";"LBAL1",#N/A,FALSE,"Bala";"LTES1",#N/A,FALSE,"Teso"}
Name ______________FR1: {"Lpor",#N/A,FALSE,"Porta";"LRDOS1",#N/A,FALSE,"Rdos";"LRDOS2",#N/A,FALSE,"Rdos";"LBAL1",#N/A,FALSE,"Bala";"LTES1",#N/A,FALSE,"Teso"}
Name ______________FR1: {"Lpor",#N/A,FALSE,"Porta";"LRDOS1",#N/A,FALSE,"Rdos";"LRDOS2",#N/A,FALSE,"Rdos";"LBAL1",#N/A,FALSE,"Bala";"LTES1",#N/A,FALSE,"Teso"}
Name _____________FR1: {"Lpor",#N/A,FALSE,"Porta";"LRDOS1",#N/A,FALSE,"Rdos";"LRDOS2",#N/A,FALSE,"Rdos";"LBAL1",#N/A,FALSE,"Bala";"LTES1",#N/A,FALSE,"Teso"}
Name _____________FR1: {"Lpor",#N/A,FALSE,"Porta";"LRDOS1",#N/A,FALSE,"Rdos";"LRDOS2",#N/A,FALSE,"Rdos";"LBAL1",#N/A,FALSE,"Bala";"LTES1",#N/A,FALSE,"Teso"}
Name ____________FR1: {"Lpor",#N/A,FALSE,"Porta";"LRDOS1",#N/A,FALSE,"Rdos";"LRDOS2",#N/A,FALSE,"Rdos";"LBAL1",#N/A,FALSE,"Bala";"LTES1",#N/A,FALSE,"Teso"}
Name ____________FR1: {"Lpor",#N/A,FALSE,"Porta";"LRDOS1",#N/A,FALSE,"Rdos";"LRDOS2",#N/A,FALSE,"Rdos";"LBAL1",#N/A,FALSE,"Bala";"LTES1",#N/A,FALSE,"Teso"}
Name ___________FR1: {"Lpor",#N/A,FALSE,"Porta";"LRDOS1",#N/A,FALSE,"Rdos";"LRDOS2",#N/A,FALSE,"Rdos";"LBAL1",#N/A,FALSE,"Bala";"LTES1",#N/A,FALSE,"Teso"}
Name ___________FR1: {"Lpor",#N/A,FALSE,"Porta";"LRDOS1",#N/A,FALSE,"Rdos";"LRDOS2",#N/A,FALSE,"Rdos";"LBAL1",#N/A,FALSE,"Bala";"LTES1",#N/A,FALSE,"Teso"}
Name __________A330: {"Lpor",#N/A,FALSE,"Porta";"LRDOS1",#N/A,FALSE,"Rdos";"LRDOS2",#N/A,FALSE,"Rdos";"LBAL1",#N/A,FALSE,"Bala";"LTES1",#N/A,FALSE,"Teso"}
Name __________A330: {"Lpor",#N/A,FALSE,"Porta";"LRDOS1",#N/A,FALSE,"Rdos";"LRDOS2",#N/A,FALSE,"Rdos";"LBAL1",#N/A,FALSE,"Bala";"LTES1",#N/A,FALSE,"Teso"}
Name __________FR1: {"Lpor",#N/A,FALSE,"Porta";"LRDOS1",#N/A,FALSE,"Rdos";"LRDOS2",#N/A,FALSE,"Rdos";"LBAL1",#N/A,FALSE,"Bala";"LTES1",#N/A,FALSE,"Teso"}
Name __________FR1: {"Lpor",#N/A,FALSE,"Porta";"LRDOS1",#N/A,FALSE,"Rdos";"LRDOS2",#N/A,FALSE,"Rdos";"LBAL1",#N/A,FALSE,"Bala";"LTES1",#N/A,FALSE,"Teso"}
Name _________A330: {"Lpor",#N/A,FALSE,"Porta";"LRDOS1",#N/A,FALSE,"Rdos";"LRDOS2",#N/A,FALSE,"Rdos";"LBAL1",#N/A,FALSE,"Bala";"LTES1",#N/A,FALSE,"Teso"}
Name _________A330: {"Lpor",#N/A,FALSE,"Porta";"LRDOS1",#N/A,FALSE,"Rdos";"LRDOS2",#N/A,FALSE,"Rdos";"LBAL1",#N/A,FALSE,"Bala";"LTES1",#N/A,FALSE,"Teso"}
Name _________FR1: {"Lpor",#N/A,FALSE,"Porta";"LRDOS1",#N/A,FALSE,"Rdos";"LRDOS2",#N/A,FALSE,"Rdos";"LBAL1",#N/A,FALSE,"Bala";"LTES1",#N/A,FALSE,"Teso"}
Name _________FR1: {"Lpor",#N/A,FALSE,"Porta";"LRDOS1",#N/A,FALSE,"Rdos";"LRDOS2",#N/A,FALSE,"Rdos";"LBAL1",#N/A,FALSE,"Bala";"LTES1",#N/A,FALSE,"Teso"}
Name ________A330: {"Lpor",#N/A,FALSE,"Porta";"LRDOS1",#N/A,FALSE,"Rdos";"LRDOS2",#N/A,FALSE,"Rdos";"LBAL1",#N/A,FALSE,"Bala";"LTES1",#N/A,FALSE,"Teso"}
Name ________A330: {"Lpor",#N/A,FALSE,"Porta";"LRDOS1",#N/A,FALSE,"Rdos";"LRDOS2",#N/A,FALSE,"Rdos";"LBAL1",#N/A,FALSE,"Bala";"LTES1",#N/A,FALSE,"Teso"}
Name ________FR1: {"Lpor",#N/A,FALSE,"Porta";"LRDOS1",#N/A,FALSE,"Rdos";"LRDOS2",#N/A,FALSE,"Rdos";"LBAL1",#N/A,FALSE,"Bala";"LTES1",#N/A,FALSE,"Teso"}
Name ________FR1: {"Lpor",#N/A,FALSE,"Porta";"LRDOS1",#N/A,FALSE,"Rdos";"LRDOS2",#N/A,FALSE,"Rdos";"LBAL1",#N/A,FALSE,"Bala";"LTES1",#N/A,FALSE,"Teso"}
Name _______A330: {"Lpor",#N/A,FALSE,"Porta";"LRDOS1",#N/A,FALSE,"Rdos";"LRDOS2",#N/A,FALSE,"Rdos";"LBAL1",#N/A,FALSE,"Bala";"LTES1",#N/A,FALSE,"Teso"}
Name _______A330: {"Lpor",#N/A,FALSE,"Porta";"LRDOS1",#N/A,FALSE,"Rdos";"LRDOS2",#N/A,FALSE,"Rdos";"LBAL1",#N/A,FALSE,"Bala";"LTES1",#N/A,FALSE,"Teso"}
Name _______FR1: {"Lpor",#N/A,FALSE,"Porta";"LRDOS1",#N/A,FALSE,"Rdos";"LRDOS2",#N/A,FALSE,"Rdos";"LBAL1",#N/A,FALSE,"Bala";"LTES1",#N/A,FALSE,"Teso"}
Name _______FR1: {"Lpor",#N/A,FALSE,"Porta";"LRDOS1",#N/A,FALSE,"Rdos";"LRDOS2",#N/A,FALSE,"Rdos";"LBAL1",#N/A,FALSE,"Bala";"LTES1",#N/A,FALSE,"Teso"}
Name ______A330: {"Lpor",#N/A,FALSE,"Porta";"LRDOS1",#N/A,FALSE,"Rdos";"LRDOS2",#N/A,FALSE,"Rdos";"LBAL1",#N/A,FALSE,"Bala";"LTES1",#N/A,FALSE,"Teso"}
Name ______A330: {"Lpor",#N/A,FALSE,"Porta";"LRDOS1",#N/A,FALSE,"Rdos";"LRDOS2",#N/A,FALSE,"Rdos";"LBAL1",#N/A,FALSE,"Bala";"LTES1",#N/A,FALSE,"Teso"}
Name ______FR1: {"Lpor",#N/A,FALSE,"Porta";"LRDOS1",#N/A,FALSE,"Rdos";"LRDOS2",#N/A,FALSE,"Rdos";"LBAL1",#N/A,FALSE,"Bala";"LTES1",#N/A,FALSE,"Teso"}

Sheet Seller Case >>

Sheet Phase II Outputs
A1: TS_Output_Annual
A2: Project Ardagh
A3: Phase II Seller
A4: EV (€'m): 1,020,452.3 | EqV (€'m): 726,982.2
A5: Tab_Check | F5: #VALUE!
A6: Master_Check | F6: #VALUE!
F8: Units | G8: Input_1 | H8: Input_2 | I8: Totals | BU8: Check
D9: Period Beginning | K9: 45292 | L9: 45658 | M9: 46023 | N9: 46388 | O9: 46753 | P9: 47119 | Q9: 47484 | R9: 47849 | S9: 48214 | T9: 48580 | U9: 48945 | V9: 49310 | W9: 49675 | X9: 50041 | Y9: 50406 | Z9: 50771 | AA9: 51136 | AB9: 51502 | AC9: 51867 | AD9: 52232 | AE9: 52597 | AF9: 52963 | AG9: 53328 | AH9: 53693 | AI9: 54058 | AJ9: 54424 | AK9: 54789 | AL9: 55154 | AM9: 55519 | AN9: 55885 | AO9: 56250 | AP9: 56615 | AQ9: 56980 | AR9: 57346 | AS9: 57711 | AT9: 58076 | AU9: 58441 | AV9: 58807 | AW9: 59172 | AX9: 59537 | AY9: 59902 | AZ9: 60268 | BA9: 60633 | BB9: 60998 | BC9: 61363 | BD9: 61729 | BE9: 62094 | BF9: 62459 | BG9: 62824 | BH9: 63190 | BI9: 63555 | BJ9: 63920 | BK9: 64285 | BL9: 64651 | BM9: 65016 | BN9: 65381 | BO9: 65746 | BP9: 66112 | BQ9: 66477 | BR9: 66842 | BS9: 67207
D10: Period End | K10: 45657 | L10: 46022 | M10: 46387 | N10: 46752 | O10: 47118 | P10: 47483 | Q10: 47848 | R10: 48213 | S10: 48579 | T10: 48944 | U10: 49309 | V10: 49674 | W10: 50040 | X10: 50405 | Y10: 50770 | Z10: 51135 | AA10: 51501 | AB10: 51866 | AC10: 52231 | AD10: 52596 | AE10: 52962 | AF10: 53327 | AG10: 53692 | AH10: 54057 | AI10: 54423 | AJ10: 54788 | AK10: 55153 | AL10: 55518 | AM10: 55884 | AN10: 56249 | AO10: 56614 | AP10: 56979 | AQ10: 57345 | AR10: 57710 | AS10: 58075 | AT10: 58440 | AU10: 58806 | AV10: 59171 | AW10: 59536 | AX10: 59901 | AY10: 60267 | AZ10: 60632 | BA10: 60997 | BB10: 61362 | BC10: 61728 | BD10: 62093 | BE10: 62458 | BF10: 62823 | BG10: 63189 | BH10: 63554 | BI10: 63919 | BJ10: 64284 | BK10: 64650 | BL10: 65015 | BM10: 65380 | BN10: 65745 | BO10: 66111 | BP10: 66476 | BQ10: 66841 | BR10: 67206 | BS10: 67572
D11: Year | K11: 2024 | L11: 2025 | M11: 2026 | N11: 2027 | O11: 2028 | P11: 2029 | Q11: 2030 | R11: 2031 | S11: 2032 | T11: 2033 | U11: 2034 | V11: 2035 | W11: 2036 | X11: 2037 | Y11: 2038 | Z11: 2039 | AA11: 2040 | AB11: 2041 | AC11: 2042 | AD11: 2043 | AE11: 2044 | AF11: 2045 | AG11: 2046 | AH11: 2047 | AI11: 2048 | AJ11: 2049 | AK11: 2050 | AL11: 2051 | AM11: 2052 | AN11: 2053 | AO11: 2054 | AP11: 2055 | AQ11: 2056 | AR11: 2057 | AS11: 2058 | AT11: 2059 | AU11: 2060 | AV11: 2061 | AW11: 2062 | AX11: 2063 | AY11: 2064 | AZ11: 2065 | BA11: 2066 | BB11: 2067 | BC11: 2068 | BD11: 2069 | BE11: 2070 | BF11: 2071 | BG11: 2072 | BH11: 2073 | BI11: 2074 | BJ11: 2075 | BK11: 2076 | BL11: 2077 | BM11: 2078 | BN11: 2079 | BO11: 2080 | BP11: 2081 | BQ11: 2082 | BR11: 2083 | BS11: 2084
D12: Periods | K12: 1 | L12: 1 | M12: 2 | N12: 2 | O12: 2 | P12: 2 | Q12: 2 | R12: 2 | S12: 2 | T12: 2 | U12: 2 | V12: 2 | W12: 2 | X12: 2 | Y12: 2 | Z12: 2 | AA12: 2 | AB12: 2 | AC12: 2 | AD12: 2 | AE12: 2 | AF12: 2 | AG12: 2 | AH12: 2 | AI12: 2 | AJ12: 2 | AK12: 2 | AL12: 2 | AM12: 2 | AN12: 2 | AO12: 2 | AP12: 2 | AQ12: 2 | AR12: 2 | AS12: 2 | AT12: 2 | AU12: 2 | AV12: 2 | AW12: 2 | AX12: 2 | AY12: 2 | AZ12: 2 | BA12: 2 | BB12: 2 | BC12: 2 | BD12: 2 | BE12: 2 | BF12: 2 | BG12: 2 | BH12: 2 | BI12: 2 | BJ12: 2 | BK12: 2 | BL12: 2 | BM12: 2 | BN12: 2 | BO12: 2 | BP12: 2 | BQ12: 2 | BR12: 2 | BS12: 1
D13: Days | K13: 366 | L13: 365 | M13: 365 | N13: 365 | O13: 366 | P13: 365 | Q13: 365 | R13: 365 | S13: 366 | T13: 365 | U13: 365 | V13: 365 | W13: 366 | X13: 365 | Y13: 365 | Z13: 365 | AA13: 366 | AB13: 365 | AC13: 365 | AD13: 365 | AE13: 366 | AF13: 365 | AG13: 365 | AH13: 365 | AI13: 366 | AJ13: 365 | AK13: 365 | AL13: 365 | AM13: 366 | AN13: 365 | AO13: 365 | AP13: 365 | AQ13: 366 | AR13: 365 | AS13: 365 | AT13: 365 | AU13: 366 | AV13: 365 | AW13: 365 | AX13: 365 | AY13: 366 | AZ13: 365 | BA13: 365 | BB13: 365 | BC13: 366 | BD13: 365 | BE13: 365 | BF13: 365 | BG13: 366 | BH13: 365 | BI13: 365 | BJ13: 365 | BK13: 366 | BL13: 365 | BM13: 365 | BN13: 365 | BO13: 366 | BP13: 365 | BQ13: 365 | BR13: 365 | BS13: 182
D14: Days vs full year | K14: 0 | L14: 0 | M14: 0 | N14: 0 | O14: 0 | P14: 0 | Q14: 0 | R14: 0 | S14: 0 | T14: 0 | U14: 0 | V14: 0 | W14: 0 | X14: 0 | Y14: 0 | Z14: 0 | AA14: 0 | AB14: 0 | AC14: 0 | AD14: 0 | AE14: 0 | AF14: 0 | AG14: 0 | AH14: 0 | AI14: 0 | AJ14: 0 | AK14: 0 | AL14: 0 | AM14: 0 | AN14: 0 | AO14: 0 | AP14: 0 | AQ14: 0 | AR14: 0 | AS14: 0 | AT14: 0 | AU14: 0 | AV14: 0 | AW14: 0 | AX14: 0 | AY14: 0 | AZ14: 0 | BA14: 0 | BB14: 0 | BC14: 0 | BD14: 0 | BE14: 0 | BF14: 0 | BG14: 0 | BH14: 0 | BI14: 0 | BJ14: 0 | BK14: 0 | BL14: 0 | BM14: 0 | BN14: 0 | BO14: 0 | BP14: 0 | BQ14: 0 | BR14: 0 | BS14: -184
D15: Year Counter | K15: 1 | L15: 2 | M15: 3 | N15: 4 | O15: 5 | P15: 6 | Q15: 7 | R15: 8 | S15: 9 | T15: 10 | U15: 11 | V15: 12 | W15: 13 | X15: 14 | Y15: 15 | Z15: 16 | AA15: 17 | AB15: 18 | AC15: 19 | AD15: 20 | AE15: 21 | AF15: 22 | AG15: 23 | AH15: 24 | AI15: 25 | AJ15: 26 | AK15: 27 | AL15: 28 | AM15: 29 | AN15: 30 | AO15: 31 | AP15: 32 | AQ15: 33 | AR15: 34 | AS15: 35 | AT15: 36 | AU15: 37 | AV15: 38 | AW15: 39 | AX15: 40 | AY15: 41 | AZ15: 42 | BA15: 43 | BB15: 44 | BC15: 45 | BD15: 46 | BE15: 47 | BF15: 48 | BG15: 49 | BH15: 50 | BI15: 51 | BJ15: 52 | BK15: 53 | BL15: 54 | BM15: 55 | BN15: 56 | BO15: 57 | BP15: 58 | BQ15: 59 | BR15: 60 | BS15: 61
B17: 1 | E17: Valuation Summary
K19: 1 | L19: 2 | M19: 3 | N19: 4 | O19: 5 | P19: 6 | Q19: 7 | R19: 8 | S19: 9 | T19: 10 | U19: 11 | V19: 12 | W19: 13 | X19: 14 | Y19: 15 | Z19: 16 | AA19: 17 | AB19: 18 | AC19: 19 | AD19: 20 | AE19: 21 | AF19: 22 | AG19: 23 | AH19: 24 | AI19: 25 | AJ19: 26 | AK19: 27 | AL19: 28 | AM19: 29 | AN19: 30 | AO19: 31 | AP19: 32 | AQ19: 33 | AR19: 34 | AS19: 35 | AT19: 36 | AU19: 37 | AV19: 38 | AW19: 39 | AX19: 40 | AY19: 41 | AZ19: 42 | BA19: 43 | BB19: 44 | BC19: 45 | BD19: 46 | BE19: 47 | BF19: 48 | BG19: 49 | BH19: 50 | BI19: 51 | BJ19: 52 | BK19: 53 | BL19: 54 | BM19: 55 | BN19: 56 | BO19: 57 | BP19: 58 | BQ19: 59 | BR19: 60 | BS19: 61
E28: MW | F28: 254
E30: Production | F30: 284
E32: PPA Revenue | F32: 356
E33: Merchant Revenue | F33: 357
E34: GoOs Revenue | F34: 358
E35: Total BESS Revenue | F35: 429
E36: Other Revenue Cost/Income | F36: 430
E38: EBITDA | F38: 24
E40: Production | F40: 284
E42: OPEX | F42: 662
C46: o | E46: MW
B50: GR_W1 | E50: GR_W1 | I50: 293 | K50: 293 | L50: 0 | M50: 0 | N50: 0 | O50: 0 | P50: 0 | Q50: 0 | R50: 0 | S50: 0 | T50: 0 | U50: 0 | V50: 0 | W50: 0 | X50: 0 | Y50: 0 | Z50: 0 | AA50: 0 | AB50: 0 | AC50: 0 | AD50: 0 | AE50: 0 | AF50: 0 | AG50: 0 | AH50: 0 | AI50: 0 | AJ50: 0 | AK50: 0 | AL50: 0 | AM50: 0 | AN50: 0 | AO50: 0 | AP50: 0 | AQ50: 0 | AR50: 0 | AS50: 0 | AT50: 0 | AU50: 0 | AV50: 0 | AW50: 0 | AX50: 0 | AY50: 0 | AZ50: 0 | BA50: 0 | BB50: 0 | BC50: 0 | BD50: 0 | BE50: 0 | BF50: 0 | BG50: 0 | BH50: 0 | BI50: 0 | BJ50: 0 | BK50: 0 | BL50: 0 | BM50: 0 | BN50: 0 | BO50: 0 | BP50: 0 | BQ50: 0 | BR50: 0 | BS50: 0
E51: GR_W2 | I51: 0 | K51: 0 | L51: 0 | M51: 0 | N51: 0 | O51: 0 | P51: 0 | Q51: 0 | R51: 0 | S51: 0 | T51: 0 | U51: 0 | V51: 0 | W51: 0 | X51: 0 | Y51: 0 | Z51: 0 | AA51: 0 | AB51: 0 | AC51: 0 | AD51: 0 | AE51: 0 | AF51: 0 | AG51: 0 | AH51: 0 | AI51: 0 | AJ51: 0 | AK51: 0 | AL51: 0 | AM51: 0 | AN51: 0 | AO51: 0 | AP51: 0 | AQ51: 0 | AR51: 0 | AS51: 0 | AT51: 0 | AU51: 0 | AV51: 0 | AW51: 0 | AX51: 0 | AY51: 0 | AZ51: 0 | BA51: 0 | BB51: 0 | BC51: 0 | BD51: 0 | BE51: 0 | BF51: 0 | BG51: 0 | BH51: 0 | BI51: 0 | BJ51: 0 | BK51: 0 | BL51: 0 | BM51: 0 | BN51: 0 | BO51: 0 | BP51: 0 | BQ51: 0 | BR51: 0 | BS51: 0
E52: GR_W3 | I52: 0 | K52: 0 | L52: 0 | M52: 0 | N52: 0 | O52: 0 | P52: 0 | Q52: 0 | R52: 0 | S52: 0 | T52: 0 | U52: 0 | V52: 0 | W52: 0 | X52: 0 | Y52: 0 | Z52: 0 | AA52: 0 | AB52: 0 | AC52: 0 | AD52: 0 | AE52: 0 | AF52: 0 | AG52: 0 | AH52: 0 | AI52: 0 | AJ52: 0 | AK52: 0 | AL52: 0 | AM52: 0 | AN52: 0 | AO52: 0 | AP52: 0 | AQ52: 0 | AR52: 0 | AS52: 0 | AT52: 0 | AU52: 0 | AV52: 0 | AW52: 0 | AX52: 0 | AY52: 0 | AZ52: 0 | BA52: 0 | BB52: 0 | BC52: 0 | BD52: 0 | BE52: 0 | BF52: 0 | BG52: 0 | BH52: 0 | BI52: 0 | BJ52: 0 | BK52: 0 | BL52: 0 | BM52: 0 | BN52: 0 | BO52: 0 | BP52: 0 | BQ52: 0 | BR52: 0 | BS52: 0
E53: GR_W4 | I53: 0 | K53: 0 | L53: 0 | M53: 0 | N53: 0 | O53: 0 | P53: 0 | Q53: 0 | R53: 0 | S53: 0 | T53: 0 | U53: 0 | V53: 0 | W53: 0 | X53: 0 | Y53: 0 | Z53: 0 | AA53: 0 | AB53: 0 | AC53: 0 | AD53: 0 | AE53: 0 | AF53: 0 | AG53: 0 | AH53: 0 | AI53: 0 | AJ53: 0 | AK53: 0 | AL53: 0 | AM53: 0 | AN53: 0 | AO53: 0 | AP53: 0 | AQ53: 0 | AR53: 0 | AS53: 0 | AT53: 0 | AU53: 0 | AV53: 0 | AW53: 0 | AX53: 0 | AY53: 0 | AZ53: 0 | BA53: 0 | BB53: 0 | BC53: 0 | BD53: 0 | BE53: 0 | BF53: 0 | BG53: 0 | BH53: 0 | BI53: 0 | BJ53: 0 | BK53: 0 | BL53: 0 | BM53: 0 | BN53: 0 | BO53: 0 | BP53: 0 | BQ53: 0 | BR53: 0 | BS53: 0
E54: GR_W5 | I54: 0 | K54: 0 | L54: 0 | M54: 0 | N54: 0 | O54: 0 | P54: 0 | Q54: 0 | R54: 0 | S54: 0 | T54: 0 | U54: 0 | V54: 0 | W54: 0 | X54: 0 | Y54: 0 | Z54: 0 | AA54: 0 | AB54: 0 | AC54: 0 | AD54: 0 | AE54: 0 | AF54: 0 | AG54: 0 | AH54: 0 | AI54: 0 | AJ54: 0 | AK54: 0 | AL54: 0 | AM54: 0 | AN54: 0 | AO54: 0 | AP54: 0 | AQ54: 0 | AR54: 0 | AS54: 0 | AT54: 0 | AU54: 0 | AV54: 0 | AW54: 0 | AX54: 0 | AY54: 0 | AZ54: 0 | BA54: 0 | BB54: 0 | BC54: 0 | BD54: 0 | BE54: 0 | BF54: 0 | BG54: 0 | BH54: 0 | BI54: 0 | BJ54: 0 | BK54: 0 | BL54: 0 | BM54: 0 | BN54: 0 | BO54: 0 | BP54: 0 | BQ54: 0 | BR54: 0 | BS54: 0
E55: IT_W1 | I55: 0 | K55: 0 | L55: 0 | M55: 0 | N55: 0 | O55: 0 | P55: 0 | Q55: 0 | R55: 0 | S55: 0 | T55: 0 | U55: 0 | V55: 0 | W55: 0 | X55: 0 | Y55: 0 | Z55: 0 | AA55: 0 | AB55: 0 | AC55: 0 | AD55: 0 | AE55: 0 | AF55: 0 | AG55: 0 | AH55: 0 | AI55: 0 | AJ55: 0 | AK55: 0 | AL55: 0 | AM55: 0 | AN55: 0 | AO55: 0 | AP55: 0 | AQ55: 0 | AR55: 0 | AS55: 0 | AT55: 0 | AU55: 0 | AV55: 0 | AW55: 0 | AX55: 0 | AY55: 0 | AZ55: 0 | BA55: 0 | BB55: 0 | BC55: 0 | BD55: 0 | BE55: 0 | BF55: 0 | BG55: 0 | BH55: 0 | BI55: 0 | BJ55: 0 | BK55: 0 | BL55: 0 | BM55: 0 | BN55: 0 | BO55: 0 | BP55: 0 | BQ55: 0 | BR55: 0 | BS55: 0
E56: IT_W2 | I56: 0 | K56: 0 | L56: 0 | M56: 0 | N56: 0 | O56: 0 | P56: 0 | Q56: 0 | R56: 0 | S56: 0 | T56: 0 | U56: 0 | V56: 0 | W56: 0 | X56: 0 | Y56: 0 | Z56: 0 | AA56: 0 | AB56: 0 | AC56: 0 | AD56: 0 | AE56: 0 | AF56: 0 | AG56: 0 | AH56: 0 | AI56: 0 | AJ56: 0 | AK56: 0 | AL56: 0 | AM56: 0 | AN56: 0 | AO56: 0 | AP56: 0 | AQ56: 0 | AR56: 0 | AS56: 0 | AT56: 0 | AU56: 0 | AV56: 0 | AW56: 0 | AX56: 0 | AY56: 0 | AZ56: 0 | BA56: 0 | BB56: 0 | BC56: 0 | BD56: 0 | BE56: 0 | BF56: 0 | BG56: 0 | BH56: 0 | BI56: 0 | BJ56: 0 | BK56: 0 | BL56: 0 | BM56: 0 | BN56: 0 | BO56: 0 | BP56: 0 | BQ56: 0 | BR56: 0 | BS56: 0
E57: IT_W3 | I57: 0 | K57: 0 | L57: 0 | M57: 0 | N57: 0 | O57: 0 | P57: 0 | Q57: 0 | R57: 0 | S57: 0 | T57: 0 | U57: 0 | V57: 0 | W57: 0 | X57: 0 | Y57: 0 | Z57: 0 | AA57: 0 | AB57: 0 | AC57: 0 | AD57: 0 | AE57: 0 | AF57: 0 | AG57: 0 | AH57: 0 | AI57: 0 | AJ57: 0 | AK57: 0 | AL57: 0 | AM57: 0 | AN57: 0 | AO57: 0 | AP57: 0 | AQ57: 0 | AR57: 0 | AS57: 0 | AT57: 0 | AU57: 0 | AV57: 0 | AW57: 0 | AX57: 0 | AY57: 0 | AZ57: 0 | BA57: 0 | BB57: 0 | BC57: 0 | BD57: 0 | BE57: 0 | BF57: 0 | BG57: 0 | BH57: 0 | BI57: 0 | BJ57: 0 | BK57: 0 | BL57: 0 | BM57: 0 | BN57: 0 | BO57: 0 | BP57: 0 | BQ57: 0 | BR57: 0 | BS57: 0
E58: IT_W4 | I58: 0 | K58: 0 | L58: 0 | M58: 0 | N58: 0 | O58: 0 | P58: 0 | Q58: 0 | R58: 0 | S58: 0 | T58: 0 | U58: 0 | V58: 0 | W58: 0 | X58: 0 | Y58: 0 | Z58: 0 | AA58: 0 | AB58: 0 | AC58: 0 | AD58: 0 | AE58: 0 | AF58: 0 | AG58: 0 | AH58: 0 | AI58: 0 | AJ58: 0 | AK58: 0 | AL58: 0 | AM58: 0 | AN58: 0 | AO58: 0 | AP58: 0 | AQ58: 0 | AR58: 0 | AS58: 0 | AT58: 0 | AU58: 0 | AV58: 0 | AW58: 0 | AX58: 0 | AY58: 0 | AZ58: 0 | BA58: 0 | BB58: 0 | BC58: 0 | BD58: 0 | BE58: 0 | BF58: 0 | BG58: 0 | BH58: 0 | BI58: 0 | BJ58: 0 | BK58: 0 | BL58: 0 | BM58: 0 | BN58: 0 | BO58: 0 | BP58: 0 | BQ58: 0 | BR58: 0 | BS58: 0
E59: IT_W5 | I59: 0 | K59: 0 | L59: 0 | M59: 0 | N59: 0 | O59: 0 | P59: 0 | Q59: 0 | R59: 0 | S59: 0 | T59: 0 | U59: 0 | V59: 0 | W59: 0 | X59: 0 | Y59: 0 | Z59: 0 | AA59: 0 | AB59: 0 | AC59: 0 | AD59: 0 | AE59: 0 | AF59: 0 | AG59: 0 | AH59: 0 | AI59: 0 | AJ59: 0 | AK59: 0 | AL59: 0 | AM59: 0 | AN59: 0 | AO59: 0 | AP59: 0 | AQ59: 0 | AR59: 0 | AS59: 0 | AT59: 0 | AU59: 0 | AV59: 0 | AW59: 0 | AX59: 0 | AY59: 0 | AZ59: 0 | BA59: 0 | BB59: 0 | BC59: 0 | BD59: 0 | BE59: 0 | BF59: 0 | BG59: 0 | BH59: 0 | BI59: 0 | BJ59: 0 | BK59: 0 | BL59: 0 | BM59: 0 | BN59: 0 | BO59: 0 | BP59: 0 | BQ59: 0 | BR59: 0 | BS59: 0
E60: IT_W6 | I60: 0 | K60: 0 | L60: 0 | M60: 0 | N60: 0 | O60: 0 | P60: 0 | Q60: 0 | R60: 0 | S60: 0 | T60: 0 | U60: 0 | V60: 0 | W60: 0 | X60: 0 | Y60: 0 | Z60: 0 | AA60: 0 | AB60: 0 | AC60: 0 | AD60: 0 | AE60: 0 | AF60: 0 | AG60: 0 | AH60: 0 | AI60: 0 | AJ60: 0 | AK60: 0 | AL60: 0 | AM60: 0 | AN60: 0 | AO60: 0 | AP60: 0 | AQ60: 0 | AR60: 0 | AS60: 0 | AT60: 0 | AU60: 0 | AV60: 0 | AW60: 0 | AX60: 0 | AY60: 0 | AZ60: 0 | BA60: 0 | BB60: 0 | BC60: 0 | BD60: 0 | BE60: 0 | BF60: 0 | BG60: 0 | BH60: 0 | BI60: 0 | BJ60: 0 | BK60: 0 | BL60: 0 | BM60: 0 | BN60: 0 | BO60: 0 | BP60: 0 | BQ60: 0 | BR60: 0 | BS60: 0
E61: IT_W7 | I61: 0 | K61: 0 | L61: 0 | M61: 0 | N61: 0 | O61: 0 | P61: 0 | Q61: 0 | R61: 0 | S61: 0 | T61: 0 | U61: 0 | V61: 0 | W61: 0 | X61: 0 | Y61: 0 | Z61: 0 | AA61: 0 | AB61: 0 | AC61: 0 | AD61: 0 | AE61: 0 | AF61: 0 | AG61: 0 | AH61: 0 | AI61: 0 | AJ61: 0 | AK61: 0 | AL61: 0 | AM61: 0 | AN61: 0 | AO61: 0 | AP61: 0 | AQ61: 0 | AR61: 0 | AS61: 0 | AT61: 0 | AU61: 0 | AV61: 0 | AW61: 0 | AX61: 0 | AY61: 0 | AZ61: 0 | BA61: 0 | BB61: 0 | BC61: 0 | BD61: 0 | BE61: 0 | BF61: 0 | BG61: 0 | BH61: 0 | BI61: 0 | BJ61: 0 | BK61: 0 | BL61: 0 | BM61: 0 | BN61: 0 | BO61: 0 | BP61: 0 | BQ61: 0 | BR61: 0 | BS61: 0
E62: IT_W8 | I62: 0 | K62: 0 | L62: 0 | M62: 0 | N62: 0 | O62: 0 | P62: 0 | Q62: 0 | R62: 0 | S62: 0 | T62: 0 | U62: 0 | V62: 0 | W62: 0 | X62: 0 | Y62: 0 | Z62: 0 | AA62: 0 | AB62: 0 | AC62: 0 | AD62: 0 | AE62: 0 | AF62: 0 | AG62: 0 | AH62: 0 | AI62: 0 | AJ62: 0 | AK62: 0 | AL62: 0 | AM62: 0 | AN62: 0 | AO62: 0 | AP62: 0 | AQ62: 0 | AR62: 0 | AS62: 0 | AT62: 0 | AU62: 0 | AV62: 0 | AW62: 0 | AX62: 0 | AY62: 0 | AZ62: 0 | BA62: 0 | BB62: 0 | BC62: 0 | BD62: 0 | BE62: 0 | BF62: 0 | BG62: 0 | BH62: 0 | BI62: 0 | BJ62: 0 | BK62: 0 | BL62: 0 | BM62: 0 | BN62: 0 | BO62: 0 | BP62: 0 | BQ62: 0 | BR62: 0 | BS62: 0
...

Sheet Phase II Charts
B2: Charts - Phase II Seller
P6: Date | W6: =+DATE(W7,12,31) -> 46022 | X6: =+DATE(X7,12,31) -> 46387 | Y6: =+DATE(Y7,12,31) -> 46752 | Z6: =+DATE(Z7,12,31) -> 47118 | AA6: =+DATE(AA7,12,31) -> 47483 | AB6: =+DATE(AB7,12,31) -> 47848 | AC6: =+DATE(AC7,12,31) -> 48213 | AD6: =+DATE(AD7,12,31) -> 48579 | ... BQ6: =+DATE(BQ7,12,31) -> 62823
P7: Year | W7: 2025 | X7: =W7+1 -> 2026 | Y7: =X7+1 -> 2027 | Z7: =Y7+1 -> 2028 | AA7: =Z7+1 -> 2029 | AB7: =AA7+1 -> 2030 | AC7: =AB7+1 -> 2031 | AD7: =AC7+1 -> 2032 | AE7: =AD7+1 -> 2033 | ... BQ7: =BP7+1 -> 2071
B10: =+MAX($B$6:B9)+1 -> 1 | C10: Electricity prices
C12: =+MAX($B$10:C11)+0.1 -> 1.1 | D12: Greece
P14: Electricity price - Greece | R14: €/MWh | S14: =IFERROR(AVERAGE(X14:BQ14),0) -> 0 | V14: Input
C33: =+MAX($B$10:C32)+0.1 -> 1.2 | D33: Italy
P35: Electricity price - Italy | R35: €/MWh | S35: =IFERROR(AVERAGE(X35:BQ35),0) -> 0 | V35: Input
B55: =+MAX($B$6:B54)+1 -> 2 | C55: Greek portfolio
C57: =+MAX($B$10:C56)+0.1 -> 2.1 | D57: Production
P59: Vermio North | Q59: GR_W1 | R59: GWh | S59: =SUM(X59:BQ59) -> 21081.504 | X59: ='Phase II Outputs'!M90/1000 -> 316.35352 | Y59: ='Phase II Outputs'!N90/1000 -> 576.62582 | Z59: ='Phase II Outputs'!O90/1000 -> 591.56146 | AA59: ='Phase II Outputs'!P90/1000 -> 602.63195 | AB59: ='Phase II Outputs'!Q90/1000 -> 604.27792 | AC59: ='Phase II Outputs'!R90/1000 -> 607.6466 | AD59: ='Phase II Outputs'!S90/1000 -> 613.22618 | AE59: ='Phase II Outputs'!T90/1000 -> 612.92717 | ... BQ59: ='Phase II Outputs'!BF90/1000 -> 0
P60: Vermio South | Q60: GR_W2 | R60: GWh | S60: =SUM(X60:BQ60) -> 2687.1371 | X60: ='Phase II Outputs'!M92/1000 -> 52.77888 | Y60: ='Phase II Outputs'!N92/1000 -> 73.842438 | Z60: ='Phase II Outputs'!O92/1000 -> 75.613485 | AA60: ='Phase II Outputs'!P92/1000 -> 76.875148 | AB60: ='Phase II Outputs'!Q92/1000 -> 76.953308 | AC60: ='Phase II Outputs'!R92/1000 -> 77.371997 | AD60: ='Phase II Outputs'!S92/1000 -> 78.065084 | AE60: ='Phase II Outputs'!T92/1000 -> 78.051496 | ... BQ60: ='Phase II Outputs'!BF92/1000 -> 0
P61: Mesokorfi | Q61: GR_W3 | R61: GWh | S61: =SUM(X61:BQ61) -> 2472.4185 | X61: ='Phase II Outputs'!M94/1000 -> 48.207753 | Y61: ='Phase II Outputs'!N94/1000 -> 67.936683 | Z61: ='Phase II Outputs'!O94/1000 -> 69.577564 | AA61: ='Phase II Outputs'!P94/1000 -> 70.734321 | AB61: ='Phase II Outputs'!Q94/1000 -> 70.804306 | AC61: ='Phase II Outputs'!R94/1000 -> 71.187184 | AD61: ='Phase II Outputs'!S94/1000 -> 71.818976 | AE61: ='Phase II Outputs'!T94/1000 -> 71.809054 | ... BQ61: ='Phase II Outputs'!BF94/1000 -> 0
P62: Koukouras | Q62: GR_W4 | R62: GWh | S62: =SUM(X62:BQ62) -> 3568.6076 | X62: ='Phase II Outputs'!M96/1000 -> 0 | Y62: ='Phase II Outputs'!N96/1000 -> 0 | Z62: ='Phase II Outputs'!O96/1000 -> 71.513887 | AA62: ='Phase II Outputs'!P96/1000 -> 102.48459 | AB62: ='Phase II Outputs'!Q96/1000 -> 102.42525 | AC62: ='Phase II Outputs'!R96/1000 -> 102.85364 | AD62: ='Phase II Outputs'!S96/1000 -> 103.81889 | AE62: ='Phase II Outputs'!T96/1000 -> 103.76979 | ... BQ62: ='Phase II Outputs'!BF96/1000 -> 0
P63: Panachaiko III | Q63: GR_W5 | R63: GWh | S63: =SUM(X63:BQ63) -> 1372.2766 | X63: ='Phase II Outputs'!M98/1000 -> 0 | Y63: ='Phase II Outputs'!N98/1000 -> 0 | Z63: ='Phase II Outputs'!O98/1000 -> 18.406272 | AA63: ='Phase II Outputs'!P98/1000 -> 39.09836 | AB63: ='Phase II Outputs'!Q98/1000 -> 39.276387 | AC63: ='Phase II Outputs'!R98/1000 -> 39.460839 | AD63: ='Phase II Outputs'!S98/1000 -> 39.812085 | AE63: ='Phase II Outputs'!T98/1000 -> 39.792045 | ... BQ63: ='Phase II Outputs'!BF98/1000 -> 0
P64: Total production | R64: GWh | S64: =SUM(X64:BQ64) -> 31181.944 | X64: =SUM(X59:X63) -> 417.34015 | Y64: =SUM(Y59:Y63) -> 718.40494 | Z64: =SUM(Z59:Z63) -> 826.67267 | AA64: =SUM(AA59:AA63) -> 891.82436 | AB64: =SUM(AB59:AB63) -> 893.73718 | AC64: =SUM(AC59:AC63) -> 898.52026 | AD64: =SUM(AD59:AD63) -> 906.74121 | AE64: =SUM(AE59:AE63) -> 906.34956 | ... BQ64: =SUM(BQ59:BQ63) -> 0
C78: =+MAX($B$10:C77)+0.1 -> 2.2 | D78: Revenues
P80: Vermio North | Q80: GR_W1 | R80: €m | S80: =SUM(X80:BQ80) -> 667.76083 | X80: ='Phase II Outputs'!M161/1000 -> 14.592562 | Y80: ='Phase II Outputs'!N161/1000 -> 42.67031 | Z80: ='Phase II Outputs'!O161/1000 -> 43.775548 | AA80: ='Phase II Outputs'!P161/1000 -> 44.594764 | AB80: ='Phase II Outputs'!Q161/1000 -> 44.716566 | AC80: ='Phase II Outputs'!R161/1000 -> 44.965849 | AD80: ='Phase II Outputs'!S161/1000 -> 45.378737 | AE80: ='Phase II Outputs'!T161/1000 -> 45.356611 | ... BQ80: ='Phase II Outputs'!BF161/1000 -> 0
P81: Vermio South | Q81: GR_W2 | R81: €m | S81: =SUM(X81:BQ81) -> 85.160313 | X81: ='Phase II Outputs'!M169/1000 -> 1.6431206 | Y81: ='Phase II Outputs'!N169/1000 -> 5.3166556 | Z81: ='Phase II Outputs'!O169/1000 -> 5.4441709 | AA81: ='Phase II Outputs'!P169/1000 -> 5.5350106 | AB81: ='Phase II Outputs'!Q169/1000 -> 5.5406382 | AC81: ='Phase II Outputs'!R169/1000 -> 5.5707838 | AD81: ='Phase II Outputs'!S169/1000 -> 5.620686 | AE81: ='Phase II Outputs'!T169/1000 -> 5.6197077 | ... BQ81: ='Phase II Outputs'!BF169/1000 -> 0
P82: Mesokorfi | Q82: GR_W3 | R82: €m | S82: =SUM(X82:BQ82) -> 78.318613 | X82: ='Phase II Outputs'!M177/1000 -> 1.4806687 | Y82: ='Phase II Outputs'!N177/1000 -> 4.8914412 | Z82: ='Phase II Outputs'!O177/1000 -> 5.0095846 | AA82: ='Phase II Outputs'!P177/1000 -> 5.0928711 | AB82: ='Phase II Outputs'!Q177/1000 -> 5.09791 | AC82: ='Phase II Outputs'!R177/1000 -> 5.1254773 | AD82: ='Phase II Outputs'!S177/1000 -> 5.1709663 | AE82: ='Phase II Outputs'!T177/1000 -> 5.1702519 | ... BQ82: ='Phase II Outputs'!BF177/1000 -> 0
P83: Koukouras | Q83: GR_W4 | R83: €m | S83: =SUM(X83:BQ83) -> 108.42455 | X83: ='Phase II Outputs'!M185/1000 -> 0 | Y83: ='Phase II Outputs'!N185/1000 -> 0 | Z83: ='Phase II Outputs'!O185/1000 -> 4.9344582 | AA83: ='Phase II Outputs'!P185/1000 -> 7.0714365 | AB83: ='Phase II Outputs'!Q185/1000 -> 7.0673424 | AC83: ='Phase II Outputs'!R185/1000 -> 7.0969013 | AD83: ='Phase II Outputs'!S185/1000 -> 7.1635031 | AE83: ='Phase II Outputs'!T185/1000 -> 7.1601157 | ... BQ83: ='Phase II Outputs'!BF185/1000 -> 0
P84: Panachaiko III | Q84: GR_W5 | R84: €m | S84: =SUM(X84:BQ84) -> 0 | X84: ='Phase II Outputs'!M193/1000 -> 0 | Y84: ='Phase II Outputs'!N193/1000 -> 0 | Z84: ='Phase II Outputs'!O193/1000 -> 0 | AA84: ='Phase II Outputs'!P193/1000 -> 0 | AB84: ='Phase II Outputs'!Q193/1000 -> 0 | AC84: ='Phase II Outputs'!R193/1000 -> 0 | AD84: ='Phase II Outputs'!S193/1000 -> 0 | AE84: ='Phase II Outputs'!T193/1000 -> 0 | ... BQ84: ='Phase II Outputs'!BF193/1000 -> 0
P85: PPA revenue | R85: €m | S85: =SUM(X85:BQ85) -> 939.6643 | X85: =SUM(X80:X84) -> 17.716351 | Y85: =SUM(Y80:Y84) -> 52.878407 | Z85: =SUM(Z80:Z84) -> 59.163762 | AA85: =SUM(AA80:AA84) -> 62.294082 | AB85: =SUM(AB80:AB84) -> 62.422457 | AC85: =SUM(AC80:AC84) -> 62.759011 | AD85: =SUM(AD80:AD84) -> 63.333893 | AE85: =SUM(AE80:AE84) -> 63.306686 | ... BQ85: =SUM(BQ80:BQ84) -> 0
P86: Vermio North | Q86: GR_W1 | R86: €m | S86: =SUM(X86:BQ86) -> 1614.3122 | X86: ='Phase II Outputs'!M162/1000 -> 12.806804 | Y86: ='Phase II Outputs'!N162/1000 -> 0 | Z86: ='Phase II Outputs'!O162/1000 -> 0 | AA86: ='Phase II Outputs'!P162/1000 -> 0 | AB86: ='Phase II Outputs'!Q162/1000 -> 0 | AC86: ='Phase II Outputs'!R162/1000 -> 0 | AD86: ='Phase II Outputs'!S162/1000 -> 0 | AE86: ='Phase II Outputs'!T162/1000 -> 0 | ... BQ86: ='Phase II Outputs'!BF162/1000 -> 0
P87: Vermio South | Q87: GR_W2 | R87: €m | S87: =SUM(X87:BQ87) -> 201.554 | X87: ='Phase II Outputs'!M170/1000 -> 3.1696198 | Y87: ='Phase II Outputs'!N170/1000 -> 0 | Z87: ='Phase II Outputs'!O170/1000 -> 0 | AA87: ='Phase II Outputs'!P170/1000 -> 0 | AB87: ='Phase II Outputs'!Q170/1000 -> 0 | AC87: ='Phase II Outputs'!R170/1000 -> 0 | AD87: ='Phase II Outputs'!S170/1000 -> 0 | AE87: ='Phase II Outputs'!T170/1000 -> 0 | ... BQ87: ='Phase II Outputs'!BF170/1000 -> 0
P88: Mesokorfi | Q88: GR_W3 | R88: €m | S88: =SUM(X88:BQ88) -> 185.52491 | X88: ='Phase II Outputs'!M178/1000 -> 2.922306 | Y88: ='Phase II Outputs'!N178/1000 -> 0 | Z88: ='Phase II Outputs'!O178/1000 -> 0 | AA88: ='Phase II Outputs'!P178/1000 -> 0 | AB88: ='Phase II Outputs'!Q178/1000 -> 0 | AC88: ='Phase II Outputs'!R178/1000 -> 0 | AD88: ='Phase II Outputs'!S178/1000 -> 0 | AE88: ='Phase II Outputs'!T178/1000 -> 0 | ... BQ88: ='Phase II Outputs'!BF178/1000 -> 0
P89: Koukouras | Q89: GR_W4 | R89: €m | S89: =SUM(X89:BQ89) -> 276.13793 | X89: ='Phase II Outputs'!M186/1000 -> 0 | Y89: ='Phase II Outputs'!N186/1000 -> 0 | Z89: ='Phase II Outputs'!O186/1000 -> 0 | AA89: ='Phase II Outputs'!P186/1000 -> 0 | AB89: ='Phase II Outputs'!Q186/1000 -> 0 | AC89: ='Phase II Outputs'!R186/1000 -> 0 | AD89: ='Phase II Outputs'!S186/1000 -> 0 | AE89: ='Phase II Outputs'!T186/1000 -> 0 | ... BQ89: ='Phase II Outputs'!BF186/1000 -> 0
P90: Panachaiko III | Q90: GR_W5 | R90: €m | S90: =SUM(X90:BQ90) -> 174.12671 | X90: ='Phase II Outputs'!M194/1000 -> 0 | Y90: ='Phase II Outputs'!N194/1000 -> 0 | Z90: ='Phase II Outputs'!O194/1000 -> 2.0688658 | AA90: ='Phase II Outputs'!P194/1000 -> 4.2188711 | AB90: ='Phase II Outputs'!Q194/1000 -> 3.9698685 | AC90: ='Phase II Outputs'!R194/1000 -> 4.2201171 | AD90: ='Phase II Outputs'!S194/1000 -> 4.315261 | AE90: ='Phase II Outputs'!T194/1000 -> 4.4930535 | ... BQ90: ='Phase II Outputs'!BF194/1000 -> 0
P91: Merchant revenue | R91: €m | S91: =SUM(X91:BQ91) -> 2451.6557 | X91: =SUM(X86:X90) -> 18.898729 | Y91: =SUM(Y86:Y90) -> 0 | Z91: =SUM(Z86:Z90) -> 2.0688658 | AA91: =SUM(AA86:AA90) -> 4.2188711 | AB91: =SUM(AB86:AB90) -> 3.9698685 | AC91: =SUM(AC86:AC90) -> 4.2201171 | AD91: =SUM(AD86:AD90) -> 4.315261 | AE91: =SUM(AE86:AE90) -> 4.4930535 | ... BQ91: =SUM(BQ86:BQ90) -> 0
P92: Vermio North | Q92: GR_W1 | R92: €m | S92: =SUM(X92:BQ92) -> 55.941759 | X92: ='Phase II Outputs'!M163/1000 -> 0.10014077 | Y92: ='Phase II Outputs'!N163/1000 -> 0 | Z92: ='Phase II Outputs'!O163/1000 -> 0 | AA92: ='Phase II Outputs'!P163/1000 -> 0 | AB92: ='Phase II Outputs'!Q163/1000 -> 0 | AC92: ='Phase II Outputs'!R163/1000 -> 0 | AD92: ='Phase II Outputs'!S163/1000 -> 0 | AE92: ='Phase II Outputs'!T163/1000 -> 0 | ... BQ92: ='Phase II Outputs'!BF163/1000 -> 0
P93: Vermio South | Q93: GR_W2 | R93: €m | S93: =SUM(X93:BQ93) -> 6.9067339 | X93: ='Phase II Outputs'!M171/1000 -> 0 | Y93: ='Phase II Outputs'!N171/1000 -> 0 | Z93: ='Phase II Outputs'!O171/1000 -> 0 | AA93: ='Phase II Outputs'!P171/1000 -> 0 | AB93: ='Phase II Outputs'!Q171/1000 -> 0 | AC93: ='Phase II Outputs'!R171/1000 -> 0 | AD93: ='Phase II Outputs'!S171/1000 -> 0 | AE93: ='Phase II Outputs'!T171/1000 -> 0 | ... BQ93: ='Phase II Outputs'!BF171/1000 -> 0
P94: Mesokorfi | Q94: GR_W3 | R94: €m | S94: =SUM(X94:BQ94) -> 6.3572886 | X94: ='Phase II Outputs'!M179/1000 -> 0 | Y94: ='Phase II Outputs'!N179/1000 -> 0 | Z94: ='Phase II Outputs'!O179/1000 -> 0 | AA94: ='Phase II Outputs'!P179/1000 -> 0 | AB94: ='Phase II Outputs'!Q179/1000 -> 0 | AC94: ='Phase II Outputs'!R179/1000 -> 0 | AD94: ='Phase II Outputs'!S179/1000 -> 0 | AE94: ='Phase II Outputs'!T179/1000 -> 0 | ... BQ94: ='Phase II Outputs'!BF179/1000 -> 0
P95: Koukouras | Q95: GR_W4 | R95: €m | S95: =SUM(X95:BQ95) -> 9.5680297 | X95: ='Phase II Outputs'!M187/1000 -> 0 | Y95: ='Phase II Outputs'!N187/1000 -> 0 | Z95: ='Phase II Outputs'!O187/1000 -> 0 | AA95: ='Phase II Outputs'!P187/1000 -> 0 | AB95: ='Phase II Outputs'!Q187/1000 -> 0 | AC95: ='Phase II Outputs'!R187/1000 -> 0 | AD95: ='Phase II Outputs'!S187/1000 -> 0 | AE95: ='Phase II Outputs'!T187/1000 -> 0 | ... BQ95: ='Phase II Outputs'!BF187/1000 -> 0
P96: Panachaiko III | Q96: GR_W5 | R96: €m | S96: =SUM(X96:BQ96) -> 6.1665263 | X96: ='Phase II Outputs'!M195/1000 -> 0 | Y96: ='Phase II Outputs'!N195/1000 -> 0 | Z96: ='Phase II Outputs'!O195/1000 -> 0.049071769 | AA96: ='Phase II Outputs'!P195/1000 -> 0.12333393 | AB96: ='Phase II Outputs'!Q195/1000 -> 0.13944653 | AC96: ='Phase II Outputs'!R195/1000 -> 0.15406777 | AD96: ='Phase II Outputs'!S195/1000 -> 0.16314352 | AE96: ='Phase II Outputs'!T195/1000 -> 0.1686652 | ... BQ96: ='Phase II Outputs'!BF195/1000 -> 0
P97: GoOs revenue | R97: €m | S97: =SUM(X97:BQ97) -> 84.940338 | X97: =SUM(X92:X96) -> 0.10014077 | Y97: =SUM(Y92:Y96) -> 0 | Z97: =SUM(Z92:Z96) -> 0.049071769 | AA97: =SUM(AA92:AA96) -> 0.12333393 | AB97: =SUM(AB92:AB96) -> 0.13944653 | AC97: =SUM(AC92:AC96) -> 0.15406777 | AD97: =SUM(AD92:AD96) -> 0.16314352 | AE97: =SUM(AE92:AE96) -> 0.1686652 | ... BQ97: =SUM(BQ92:BQ96) -> 0
P98: Vermio North | Q98: GR_W1 | R98: €m | S98: =SUM(X98:BQ98) -> -34.360502 | X98: ='Phase II Outputs'!M166/1000 -> -0.52536008 | Y98: ='Phase II Outputs'!N166/1000 -> -1.1532516 | Z98: ='Phase II Outputs'!O166/1000 -> -1.1831229 | AA98: ='Phase II Outputs'!P166/1000 -> 6.4862301 | AB98: ='Phase II Outputs'!Q166/1000 -> -1.2085558 | AC98: ='Phase II Outputs'!R166/1000 -> -1.2152932 | AD98: ='Phase II Outputs'!S166/1000 -> -1.2264524 | AE98: ='Phase II Outputs'!T166/1000 -> -1.2258543 | ... BQ98: ='Phase II Outputs'!BF166/1000 -> 0
P99: Vermio South | Q99: GR_W2 | R99: €m | S99: =SUM(X99:BQ99) -> -8.6119607 | X99: ='Phase II Outputs'!M174/1000 -> -0.21925696 | Y99: ='Phase II Outputs'!N174/1000 -> -0.14768488 | Z99: ='Phase II Outputs'!O174/1000 -> -0.15122697 | AA99: ='Phase II Outputs'!P174/1000 -> -0.1537503 | AB99: ='Phase II Outputs'!Q174/1000 -> -0.15390662 | AC99: ='Phase II Outputs'!R174/1000 -> -0.15474399 | AD99: ='Phase II Outputs'!S174/1000 -> -0.15613017 | AE99: ='Phase II Outputs'!T174/1000 -> -0.15610299 | ... BQ99: ='Phase II Outputs'!BF174/1000 -> 0
P100: Mesokorfi | Q100: GR_W3 | R100: €m | S100: =SUM(X100:BQ100) -> -8.189432 | X100: ='Phase II Outputs'!M182/1000 -> -0.21235264 | Y100: ='Phase II Outputs'!N182/1000 -> -0.13587337 | Z100: ='Phase II Outputs'!O182/1000 -> -0.13915513 | AA100: ='Phase II Outputs'!P182/1000 -> -0.14146864 | AB100: ='Phase II Outputs'!Q182/1000 -> -0.14160861 | AC100: ='Phase II Outputs'!R182/1000 -> -0.14237437 | AD100: ='Phase II Outputs'!S182/1000 -> -0.14363795 | AE100: ='Phase II Outputs'!T182/1000 -> -0.14361811 | ... BQ100: ='Phase II Outputs'!BF182/1000 -> 0
P101: Koukouras | Q101: GR_W4 | R101: €m | S101: =SUM(X101:BQ101) -> -2.3599945 | X101: ='Phase II Outputs'!M190/1000 -> 0 | Y101: ='Phase II Outputs'!N190/1000 -> 0 | Z101: ='Phase II Outputs'!O190/1000 -> -0.12791396 | AA101: ='Phase II Outputs'!P190/1000 -> -0.20496917 | AB101: ='Phase II Outputs'!Q190/1000 -> -0.2048505 | AC101: ='Phase II Outputs'!R190/1000 -> 7.7124227 | AD101: ='Phase II Outputs'!S190/1000 -> -0.20763777 | AE101: ='Phase II Outputs'!T190/1000 -> -0.20753959 | ... BQ101: ='Phase II Outputs'!BF190/1000 -> 0
P102: Panachaiko III | Q102: GR_W5 | R102: €m | S102: =SUM(X102:BQ102) -> -8.6785531 | X102: ='Phase II Outputs'!M198/1000 -> 0 | Y102: ='Phase II Outputs'!N198/1000 -> 0 | Z102: ='Phase II Outputs'!O198/1000 -> -0.14221254 | AA102: ='Phase II Outputs'!P198/1000 -> -0.27659672 | AB102: ='Phase II Outputs'!Q198/1000 -> -0.26075277 | AC102: ='Phase II Outputs'!R198/1000 -> -0.26792168 | AD102: ='Phase II Outputs'!S198/1000 -> -0.26742417 | AE102: ='Phase II Outputs'!T198/1000 -> -0.27138409 | ... BQ102: ='Phase II Outputs'!BF198/1000 -> 0
...

Sheet NBO Case >>

Sheet NBO Case Outputs
A1: TS_Output_Annual
A2: Project Ardagh
A3: Phase II Seller
A4: EV (€'m): 1,020,452.3 | EqV (€'m): 726,982.2
A5: Tab_Check | F5: #VALUE!
A6: Master_Check | F6: #VALUE!
F8: Units | G8: Input_1 | H8: Input_2 | I8: Totals | BU8: Check
D9: Period Beginning | K9: 45292 | L9: 45658 | M9: 46023 | N9: 46388 | O9: 46753 | P9: 47119 | Q9: 47484 | R9: 47849 | S9: 48214 | T9: 48580 | U9: 48945 | V9: 49310 | W9: 49675 | X9: 50041 | Y9: 50406 | Z9: 50771 | AA9: 51136 | AB9: 51502 | AC9: 51867 | AD9: 52232 | AE9: 52597 | AF9: 52963 | AG9: 53328 | AH9: 53693 | AI9: 54058 | AJ9: 54424 | AK9: 54789 | AL9: 55154 | AM9: 55519 | AN9: 55885 | AO9: 56250 | AP9: 56615 | AQ9: 56980 | AR9: 57346 | AS9: 57711 | AT9: 58076 | AU9: 58441 | AV9: 58807 | AW9: 59172 | AX9: 59537 | AY9: 59902 | AZ9: 60268 | BA9: 60633 | BB9: 60998 | BC9: 61363 | BD9: 61729 | BE9: 62094 | BF9: 62459 | BG9: 62824 | BH9: 63190 | BI9: 63555 | BJ9: 63920 | BK9: 64285 | BL9: 64651 | BM9: 65016 | BN9: 65381 | BO9: 65746 | BP9: 66112 | BQ9: 66477 | BR9: 66842 | BS9: 67207
D10: Period End | K10: 45657 | L10: 46022 | M10: 46387 | N10: 46752 | O10: 47118 | P10: 47483 | Q10: 47848 | R10: 48213 | S10: 48579 | T10: 48944 | U10: 49309 | V10: 49674 | W10: 50040 | X10: 50405 | Y10: 50770 | Z10: 51135 | AA10: 51501 | AB10: 51866 | AC10: 52231 | AD10: 52596 | AE10: 52962 | AF10: 53327 | AG10: 53692 | AH10: 54057 | AI10: 54423 | AJ10: 54788 | AK10: 55153 | AL10: 55518 | AM10: 55884 | AN10: 56249 | AO10: 56614 | AP10: 56979 | AQ10: 57345 | AR10: 57710 | AS10: 58075 | AT10: 58440 | AU10: 58806 | AV10: 59171 | AW10: 59536 | AX10: 59901 | AY10: 60267 | AZ10: 60632 | BA10: 60997 | BB10: 61362 | BC10: 61728 | BD10: 62093 | BE10: 62458 | BF10: 62823 | BG10: 63189 | BH10: 63554 | BI10: 63919 | BJ10: 64284 | BK10: 64650 | BL10: 65015 | BM10: 65380 | BN10: 65745 | BO10: 66111 | BP10: 66476 | BQ10: 66841 | BR10: 67206 | BS10: 67572
D11: Year | K11: 2024 | L11: 2025 | M11: 2026 | N11: 2027 | O11: 2028 | P11: 2029 | Q11: 2030 | R11: 2031 | S11: 2032 | T11: 2033 | U11: 2034 | V11: 2035 | W11: 2036 | X11: 2037 | Y11: 2038 | Z11: 2039 | AA11: 2040 | AB11: 2041 | AC11: 2042 | AD11: 2043 | AE11: 2044 | AF11: 2045 | AG11: 2046 | AH11: 2047 | AI11: 2048 | AJ11: 2049 | AK11: 2050 | AL11: 2051 | AM11: 2052 | AN11: 2053 | AO11: 2054 | AP11: 2055 | AQ11: 2056 | AR11: 2057 | AS11: 2058 | AT11: 2059 | AU11: 2060 | AV11: 2061 | AW11: 2062 | AX11: 2063 | AY11: 2064 | AZ11: 2065 | BA11: 2066 | BB11: 2067 | BC11: 2068 | BD11: 2069 | BE11: 2070 | BF11: 2071 | BG11: 2072 | BH11: 2073 | BI11: 2074 | BJ11: 2075 | BK11: 2076 | BL11: 2077 | BM11: 2078 | BN11: 2079 | BO11: 2080 | BP11: 2081 | BQ11: 2082 | BR11: 2083 | BS11: 2084
D12: Periods | K12: 1 | L12: 1 | M12: 2 | N12: 2 | O12: 2 | P12: 2 | Q12: 2 | R12: 2 | S12: 2 | T12: 2 | U12: 2 | V12: 2 | W12: 2 | X12: 2 | Y12: 2 | Z12: 2 | AA12: 2 | AB12: 2 | AC12: 2 | AD12: 2 | AE12: 2 | AF12: 2 | AG12: 2 | AH12: 2 | AI12: 2 | AJ12: 2 | AK12: 2 | AL12: 2 | AM12: 2 | AN12: 2 | AO12: 2 | AP12: 2 | AQ12: 2 | AR12: 2 | AS12: 2 | AT12: 2 | AU12: 2 | AV12: 2 | AW12: 2 | AX12: 2 | AY12: 2 | AZ12: 2 | BA12: 2 | BB12: 2 | BC12: 2 | BD12: 2 | BE12: 2 | BF12: 2 | BG12: 2 | BH12: 2 | BI12: 2 | BJ12: 2 | BK12: 2 | BL12: 2 | BM12: 2 | BN12: 2 | BO12: 2 | BP12: 2 | BQ12: 2 | BR12: 2 | BS12: 1
D13: Days | K13: 366 | L13: 365 | M13: 365 | N13: 365 | O13: 366 | P13: 365 | Q13: 365 | R13: 365 | S13: 366 | T13: 365 | U13: 365 | V13: 365 | W13: 366 | X13: 365 | Y13: 365 | Z13: 365 | AA13: 366 | AB13: 365 | AC13: 365 | AD13: 365 | AE13: 366 | AF13: 365 | AG13: 365 | AH13: 365 | AI13: 366 | AJ13: 365 | AK13: 365 | AL13: 365 | AM13: 366 | AN13: 365 | AO13: 365 | AP13: 365 | AQ13: 366 | AR13: 365 | AS13: 365 | AT13: 365 | AU13: 366 | AV13: 365 | AW13: 365 | AX13: 365 | AY13: 366 | AZ13: 365 | BA13: 365 | BB13: 365 | BC13: 366 | BD13: 365 | BE13: 365 | BF13: 365 | BG13: 366 | BH13: 365 | BI13: 365 | BJ13: 365 | BK13: 366 | BL13: 365 | BM13: 365 | BN13: 365 | BO13: 366 | BP13: 365 | BQ13: 365 | BR13: 365 | BS13: 182
D14: Days vs full year | K14: 0 | L14: 0 | M14: 0 | N14: 0 | O14: 0 | P14: 0 | Q14: 0 | R14: 0 | S14: 0 | T14: 0 | U14: 0 | V14: 0 | W14: 0 | X14: 0 | Y14: 0 | Z14: 0 | AA14: 0 | AB14: 0 | AC14: 0 | AD14: 0 | AE14: 0 | AF14: 0 | AG14: 0 | AH14: 0 | AI14: 0 | AJ14: 0 | AK14: 0 | AL14: 0 | AM14: 0 | AN14: 0 | AO14: 0 | AP14: 0 | AQ14: 0 | AR14: 0 | AS14: 0 | AT14: 0 | AU14: 0 | AV14: 0 | AW14: 0 | AX14: 0 | AY14: 0 | AZ14: 0 | BA14: 0 | BB14: 0 | BC14: 0 | BD14: 0 | BE14: 0 | BF14: 0 | BG14: 0 | BH14: 0 | BI14: 0 | BJ14: 0 | BK14: 0 | BL14: 0 | BM14: 0 | BN14: 0 | BO14: 0 | BP14: 0 | BQ14: 0 | BR14: 0 | BS14: -184
D15: Year Counter | K15: 1 | L15: 2 | M15: 3 | N15: 4 | O15: 5 | P15: 6 | Q15: 7 | R15: 8 | S15: 9 | T15: 10 | U15: 11 | V15: 12 | W15: 13 | X15: 14 | Y15: 15 | Z15: 16 | AA15: 17 | AB15: 18 | AC15: 19 | AD15: 20 | AE15: 21 | AF15: 22 | AG15: 23 | AH15: 24 | AI15: 25 | AJ15: 26 | AK15: 27 | AL15: 28 | AM15: 29 | AN15: 30 | AO15: 31 | AP15: 32 | AQ15: 33 | AR15: 34 | AS15: 35 | AT15: 36 | AU15: 37 | AV15: 38 | AW15: 39 | AX15: 40 | AY15: 41 | AZ15: 42 | BA15: 43 | BB15: 44 | BC15: 45 | BD15: 46 | BE15: 47 | BF15: 48 | BG15: 49 | BH15: 50 | BI15: 51 | BJ15: 52 | BK15: 53 | BL15: 54 | BM15: 55 | BN15: 56 | BO15: 57 | BP15: 58 | BQ15: 59 | BR15: 60 | BS15: 61
B17: 1 | E17: Valuation Summary
K19: 1 | L19: 2 | M19: 3 | N19: 4 | O19: 5 | P19: 6 | Q19: 7 | R19: 8 | S19: 9 | T19: 10 | U19: 11 | V19: 12 | W19: 13 | X19: 14 | Y19: 15 | Z19: 16 | AA19: 17 | AB19: 18 | AC19: 19 | AD19: 20 | AE19: 21 | AF19: 22 | AG19: 23 | AH19: 24 | AI19: 25 | AJ19: 26 | AK19: 27 | AL19: 28 | AM19: 29 | AN19: 30 | AO19: 31 | AP19: 32 | AQ19: 33 | AR19: 34 | AS19: 35 | AT19: 36 | AU19: 37 | AV19: 38 | AW19: 39 | AX19: 40 | AY19: 41 | AZ19: 42 | BA19: 43 | BB19: 44 | BC19: 45 | BD19: 46 | BE19: 47 | BF19: 48 | BG19: 49 | BH19: 50 | BI19: 51 | BJ19: 52 | BK19: 53 | BL19: 54 | BM19: 55 | BN19: 56 | BO19: 57 | BP19: 58 | BQ19: 59 | BR19: 60 | BS19: 61
E28: MW | F28: 254
E30: Production | F30: 284
E32: PPA Revenue | F32: 356
E33: Merchant Revenue | F33: 357
E34: GoOs Revenue | F34: 358
E35: Total BESS Revenue | F35: 429
E36: Other Revenue Cost/Income | F36: 430
E38: EBITDA | F38: 24
E40: Production | F40: 284
E42: OPEX | F42: 662
C46: o | E46: MW
B50: GR_W1 | E50: GR_W1 | I50: 293 | K50: 293 | L50: 0 | M50: 0 | N50: 0 | O50: 0 | P50: 0 | Q50: 0 | R50: 0 | S50: 0 | T50: 0 | U50: 0 | V50: 0 | W50: 0 | X50: 0 | Y50: 0 | Z50: 0 | AA50: 0 | AB50: 0 | AC50: 0 | AD50: 0 | AE50: 0 | AF50: 0 | AG50: 0 | AH50: 0 | AI50: 0 | AJ50: 0 | AK50: 0 | AL50: 0 | AM50: 0 | AN50: 0 | AO50: 0 | AP50: 0 | AQ50: 0 | AR50: 0 | AS50: 0 | AT50: 0 | AU50: 0 | AV50: 0 | AW50: 0 | AX50: 0 | AY50: 0 | AZ50: 0 | BA50: 0 | BB50: 0 | BC50: 0 | BD50: 0 | BE50: 0 | BF50: 0 | BG50: 0 | BH50: 0 | BI50: 0 | BJ50: 0 | BK50: 0 | BL50: 0 | BM50: 0 | BN50: 0 | BO50: 0 | BP50: 0 | BQ50: 0 | BR50: 0 | BS50: 0
E51: GR_W2 | I51: 0 | K51: 0 | L51: 0 | M51: 0 | N51: 0 | O51: 0 | P51: 0 | Q51: 0 | R51: 0 | S51: 0 | T51: 0 | U51: 0 | V51: 0 | W51: 0 | X51: 0 | Y51: 0 | Z51: 0 | AA51: 0 | AB51: 0 | AC51: 0 | AD51: 0 | AE51: 0 | AF51: 0 | AG51: 0 | AH51: 0 | AI51: 0 | AJ51: 0 | AK51: 0 | AL51: 0 | AM51: 0 | AN51: 0 | AO51: 0 | AP51: 0 | AQ51: 0 | AR51: 0 | AS51: 0 | AT51: 0 | AU51: 0 | AV51: 0 | AW51: 0 | AX51: 0 | AY51: 0 | AZ51: 0 | BA51: 0 | BB51: 0 | BC51: 0 | BD51: 0 | BE51: 0 | BF51: 0 | BG51: 0 | BH51: 0 | BI51: 0 | BJ51: 0 | BK51: 0 | BL51: 0 | BM51: 0 | BN51: 0 | BO51: 0 | BP51: 0 | BQ51: 0 | BR51: 0 | BS51: 0
E52: GR_W3 | I52: 0 | K52: 0 | L52: 0 | M52: 0 | N52: 0 | O52: 0 | P52: 0 | Q52: 0 | R52: 0 | S52: 0 | T52: 0 | U52: 0 | V52: 0 | W52: 0 | X52: 0 | Y52: 0 | Z52: 0 | AA52: 0 | AB52: 0 | AC52: 0 | AD52: 0 | AE52: 0 | AF52: 0 | AG52: 0 | AH52: 0 | AI52: 0 | AJ52: 0 | AK52: 0 | AL52: 0 | AM52: 0 | AN52: 0 | AO52: 0 | AP52: 0 | AQ52: 0 | AR52: 0 | AS52: 0 | AT52: 0 | AU52: 0 | AV52: 0 | AW52: 0 | AX52: 0 | AY52: 0 | AZ52: 0 | BA52: 0 | BB52: 0 | BC52: 0 | BD52: 0 | BE52: 0 | BF52: 0 | BG52: 0 | BH52: 0 | BI52: 0 | BJ52: 0 | BK52: 0 | BL52: 0 | BM52: 0 | BN52: 0 | BO52: 0 | BP52: 0 | BQ52: 0 | BR52: 0 | BS52: 0
E53: GR_W4 | I53: 0 | K53: 0 | L53: 0 | M53: 0 | N53: 0 | O53: 0 | P53: 0 | Q53: 0 | R53: 0 | S53: 0 | T53: 0 | U53: 0 | V53: 0 | W53: 0 | X53: 0 | Y53: 0 | Z53: 0 | AA53: 0 | AB53: 0 | AC53: 0 | AD53: 0 | AE53: 0 | AF53: 0 | AG53: 0 | AH53: 0 | AI53: 0 | AJ53: 0 | AK53: 0 | AL53: 0 | AM53: 0 | AN53: 0 | AO53: 0 | AP53: 0 | AQ53: 0 | AR53: 0 | AS53: 0 | AT53: 0 | AU53: 0 | AV53: 0 | AW53: 0 | AX53: 0 | AY53: 0 | AZ53: 0 | BA53: 0 | BB53: 0 | BC53: 0 | BD53: 0 | BE53: 0 | BF53: 0 | BG53: 0 | BH53: 0 | BI53: 0 | BJ53: 0 | BK53: 0 | BL53: 0 | BM53: 0 | BN53: 0 | BO53: 0 | BP53: 0 | BQ53: 0 | BR53: 0 | BS53: 0
E54: GR_W5 | I54: 0 | K54: 0 | L54: 0 | M54: 0 | N54: 0 | O54: 0 | P54: 0 | Q54: 0 | R54: 0 | S54: 0 | T54: 0 | U54: 0 | V54: 0 | W54: 0 | X54: 0 | Y54: 0 | Z54: 0 | AA54: 0 | AB54: 0 | AC54: 0 | AD54: 0 | AE54: 0 | AF54: 0 | AG54: 0 | AH54: 0 | AI54: 0 | AJ54: 0 | AK54: 0 | AL54: 0 | AM54: 0 | AN54: 0 | AO54: 0 | AP54: 0 | AQ54: 0 | AR54: 0 | AS54: 0 | AT54: 0 | AU54: 0 | AV54: 0 | AW54: 0 | AX54: 0 | AY54: 0 | AZ54: 0 | BA54: 0 | BB54: 0 | BC54: 0 | BD54: 0 | BE54: 0 | BF54: 0 | BG54: 0 | BH54: 0 | BI54: 0 | BJ54: 0 | BK54: 0 | BL54: 0 | BM54: 0 | BN54: 0 | BO54: 0 | BP54: 0 | BQ54: 0 | BR54: 0 | BS54: 0
E55: IT_W1 | I55: 0 | K55: 0 | L55: 0 | M55: 0 | N55: 0 | O55: 0 | P55: 0 | Q55: 0 | R55: 0 | S55: 0 | T55: 0 | U55: 0 | V55: 0 | W55: 0 | X55: 0 | Y55: 0 | Z55: 0 | AA55: 0 | AB55: 0 | AC55: 0 | AD55: 0 | AE55: 0 | AF55: 0 | AG55: 0 | AH55: 0 | AI55: 0 | AJ55: 0 | AK55: 0 | AL55: 0 | AM55: 0 | AN55: 0 | AO55: 0 | AP55: 0 | AQ55: 0 | AR55: 0 | AS55: 0 | AT55: 0 | AU55: 0 | AV55: 0 | AW55: 0 | AX55: 0 | AY55: 0 | AZ55: 0 | BA55: 0 | BB55: 0 | BC55: 0 | BD55: 0 | BE55: 0 | BF55: 0 | BG55: 0 | BH55: 0 | BI55: 0 | BJ55: 0 | BK55: 0 | BL55: 0 | BM55: 0 | BN55: 0 | BO55: 0 | BP55: 0 | BQ55: 0 | BR55: 0 | BS55: 0
E56: IT_W2 | I56: 0 | K56: 0 | L56: 0 | M56: 0 | N56: 0 | O56: 0 | P56: 0 | Q56: 0 | R56: 0 | S56: 0 | T56: 0 | U56: 0 | V56: 0 | W56: 0 | X56: 0 | Y56: 0 | Z56: 0 | AA56: 0 | AB56: 0 | AC56: 0 | AD56: 0 | AE56: 0 | AF56: 0 | AG56: 0 | AH56: 0 | AI56: 0 | AJ56: 0 | AK56: 0 | AL56: 0 | AM56: 0 | AN56: 0 | AO56: 0 | AP56: 0 | AQ56: 0 | AR56: 0 | AS56: 0 | AT56: 0 | AU56: 0 | AV56: 0 | AW56: 0 | AX56: 0 | AY56: 0 | AZ56: 0 | BA56: 0 | BB56: 0 | BC56: 0 | BD56: 0 | BE56: 0 | BF56: 0 | BG56: 0 | BH56: 0 | BI56: 0 | BJ56: 0 | BK56: 0 | BL56: 0 | BM56: 0 | BN56: 0 | BO56: 0 | BP56: 0 | BQ56: 0 | BR56: 0 | BS56: 0
E57: IT_W3 | I57: 0 | K57: 0 | L57: 0 | M57: 0 | N57: 0 | O57: 0 | P57: 0 | Q57: 0 | R57: 0 | S57: 0 | T57: 0 | U57: 0 | V57: 0 | W57: 0 | X57: 0 | Y57: 0 | Z57: 0 | AA57: 0 | AB57: 0 | AC57: 0 | AD57: 0 | AE57: 0 | AF57: 0 | AG57: 0 | AH57: 0 | AI57: 0 | AJ57: 0 | AK57: 0 | AL57: 0 | AM57: 0 | AN57: 0 | AO57: 0 | AP57: 0 | AQ57: 0 | AR57: 0 | AS57: 0 | AT57: 0 | AU57: 0 | AV57: 0 | AW57: 0 | AX57: 0 | AY57: 0 | AZ57: 0 | BA57: 0 | BB57: 0 | BC57: 0 | BD57: 0 | BE57: 0 | BF57: 0 | BG57: 0 | BH57: 0 | BI57: 0 | BJ57: 0 | BK57: 0 | BL57: 0 | BM57: 0 | BN57: 0 | BO57: 0 | BP57: 0 | BQ57: 0 | BR57: 0 | BS57: 0
E58: IT_W4 | I58: 0 | K58: 0 | L58: 0 | M58: 0 | N58: 0 | O58: 0 | P58: 0 | Q58: 0 | R58: 0 | S58: 0 | T58: 0 | U58: 0 | V58: 0 | W58: 0 | X58: 0 | Y58: 0 | Z58: 0 | AA58: 0 | AB58: 0 | AC58: 0 | AD58: 0 | AE58: 0 | AF58: 0 | AG58: 0 | AH58: 0 | AI58: 0 | AJ58: 0 | AK58: 0 | AL58: 0 | AM58: 0 | AN58: 0 | AO58: 0 | AP58: 0 | AQ58: 0 | AR58: 0 | AS58: 0 | AT58: 0 | AU58: 0 | AV58: 0 | AW58: 0 | AX58: 0 | AY58: 0 | AZ58: 0 | BA58: 0 | BB58: 0 | BC58: 0 | BD58: 0 | BE58: 0 | BF58: 0 | BG58: 0 | BH58: 0 | BI58: 0 | BJ58: 0 | BK58: 0 | BL58: 0 | BM58: 0 | BN58: 0 | BO58: 0 | BP58: 0 | BQ58: 0 | BR58: 0 | BS58: 0
E59: IT_W5 | I59: 0 | K59: 0 | L59: 0 | M59: 0 | N59: 0 | O59: 0 | P59: 0 | Q59: 0 | R59: 0 | S59: 0 | T59: 0 | U59: 0 | V59: 0 | W59: 0 | X59: 0 | Y59: 0 | Z59: 0 | AA59: 0 | AB59: 0 | AC59: 0 | AD59: 0 | AE59: 0 | AF59: 0 | AG59: 0 | AH59: 0 | AI59: 0 | AJ59: 0 | AK59: 0 | AL59: 0 | AM59: 0 | AN59: 0 | AO59: 0 | AP59: 0 | AQ59: 0 | AR59: 0 | AS59: 0 | AT59: 0 | AU59: 0 | AV59: 0 | AW59: 0 | AX59: 0 | AY59: 0 | AZ59: 0 | BA59: 0 | BB59: 0 | BC59: 0 | BD59: 0 | BE59: 0 | BF59: 0 | BG59: 0 | BH59: 0 | BI59: 0 | BJ59: 0 | BK59: 0 | BL59: 0 | BM59: 0 | BN59: 0 | BO59: 0 | BP59: 0 | BQ59: 0 | BR59: 0 | BS59: 0
E60: IT_W6 | I60: 0 | K60: 0 | L60: 0 | M60: 0 | N60: 0 | O60: 0 | P60: 0 | Q60: 0 | R60: 0 | S60: 0 | T60: 0 | U60: 0 | V60: 0 | W60: 0 | X60: 0 | Y60: 0 | Z60: 0 | AA60: 0 | AB60: 0 | AC60: 0 | AD60: 0 | AE60: 0 | AF60: 0 | AG60: 0 | AH60: 0 | AI60: 0 | AJ60: 0 | AK60: 0 | AL60: 0 | AM60: 0 | AN60: 0 | AO60: 0 | AP60: 0 | AQ60: 0 | AR60: 0 | AS60: 0 | AT60: 0 | AU60: 0 | AV60: 0 | AW60: 0 | AX60: 0 | AY60: 0 | AZ60: 0 | BA60: 0 | BB60: 0 | BC60: 0 | BD60: 0 | BE60: 0 | BF60: 0 | BG60: 0 | BH60: 0 | BI60: 0 | BJ60: 0 | BK60: 0 | BL60: 0 | BM60: 0 | BN60: 0 | BO60: 0 | BP60: 0 | BQ60: 0 | BR60: 0 | BS60: 0
E61: IT_W7 | I61: 0 | K61: 0 | L61: 0 | M61: 0 | N61: 0 | O61: 0 | P61: 0 | Q61: 0 | R61: 0 | S61: 0 | T61: 0 | U61: 0 | V61: 0 | W61: 0 | X61: 0 | Y61: 0 | Z61: 0 | AA61: 0 | AB61: 0 | AC61: 0 | AD61: 0 | AE61: 0 | AF61: 0 | AG61: 0 | AH61: 0 | AI61: 0 | AJ61: 0 | AK61: 0 | AL61: 0 | AM61: 0 | AN61: 0 | AO61: 0 | AP61: 0 | AQ61: 0 | AR61: 0 | AS61: 0 | AT61: 0 | AU61: 0 | AV61: 0 | AW61: 0 | AX61: 0 | AY61: 0 | AZ61: 0 | BA61: 0 | BB61: 0 | BC61: 0 | BD61: 0 | BE61: 0 | BF61: 0 | BG61: 0 | BH61: 0 | BI61: 0 | BJ61: 0 | BK61: 0 | BL61: 0 | BM61: 0 | BN61: 0 | BO61: 0 | BP61: 0 | BQ61: 0 | BR61: 0 | BS61: 0
E62: IT_W8 | I62: 0 | K62: 0 | L62: 0 | M62: 0 | N62: 0 | O62: 0 | P62: 0 | Q62: 0 | R62: 0 | S62: 0 | T62: 0 | U62: 0 | V62: 0 | W62: 0 | X62: 0 | Y62: 0 | Z62: 0 | AA62: 0 | AB62: 0 | AC62: 0 | AD62: 0 | AE62: 0 | AF62: 0 | AG62: 0 | AH62: 0 | AI62: 0 | AJ62: 0 | AK62: 0 | AL62: 0 | AM62: 0 | AN62: 0 | AO62: 0 | AP62: 0 | AQ62: 0 | AR62: 0 | AS62: 0 | AT62: 0 | AU62: 0 | AV62: 0 | AW62: 0 | AX62: 0 | AY62: 0 | AZ62: 0 | BA62: 0 | BB62: 0 | BC62: 0 | BD62: 0 | BE62: 0 | BF62: 0 | BG62: 0 | BH62: 0 | BI62: 0 | BJ62: 0 | BK62: 0 | BL62: 0 | BM62: 0 | BN62: 0 | BO62: 0 | BP62: 0 | BQ62: 0 | BR62: 0 | BS62: 0
...

Sheet NBO Case Charts
B2: Charts - NBO Case
P6: Date | W6: =+DATE(W7,12,31) -> 46022 | X6: =+DATE(X7,12,31) -> 46387 | Y6: =+DATE(Y7,12,31) -> 46752 | Z6: =+DATE(Z7,12,31) -> 47118 | AA6: =+DATE(AA7,12,31) -> 47483 | AB6: =+DATE(AB7,12,31) -> 47848 | AC6: =+DATE(AC7,12,31) -> 48213 | AD6: =+DATE(AD7,12,31) -> 48579 | ... BQ6: =+DATE(BQ7,12,31) -> 62823
P7: Year | W7: 2025 | X7: =W7+1 -> 2026 | Y7: =X7+1 -> 2027 | Z7: =Y7+1 -> 2028 | AA7: =Z7+1 -> 2029 | AB7: =AA7+1 -> 2030 | AC7: =AB7+1 -> 2031 | AD7: =AC7+1 -> 2032 | AE7: =AD7+1 -> 2033 | ... BQ7: =BP7+1 -> 2071
B10: =+MAX($B$6:B9)+1 -> 1 | C10: Electricity prices
C12: =+MAX($B$10:C11)+0.1 -> 1.1 | D12: Greece
P14: Electricity price - Greece | R14: €/MWh | S14: =IFERROR(AVERAGE(X14:BQ14),0) -> 0 | V14: Input
C33: =+MAX($B$10:C32)+0.1 -> 1.2 | D33: Italy
P35: Electricity price - Italy | R35: €/MWh | S35: =IFERROR(AVERAGE(X35:BQ35),0) -> 0 | V35: Input
B55: =+MAX($B$6:B54)+1 -> 2 | C55: Greek portfolio
C57: =+MAX($B$10:C56)+0.1 -> 2.1 | D57: Production
P59: Vermio North | Q59: GR_W1 | R59: GWh | S59: =SUM(X59:BQ59) -> 18134.357 | X59: ='NBO Case Outputs'!M90/1000 -> 313.95731 | Y59: ='NBO Case Outputs'!N90/1000 -> 593.4074 | Z59: ='NBO Case Outputs'!O90/1000 -> 603.46988 | AA59: ='NBO Case Outputs'!P90/1000 -> 607.22588 | AB59: ='NBO Case Outputs'!Q90/1000 -> 610.91577 | AC59: ='NBO Case Outputs'!R90/1000 -> 615.3588 | AD59: ='NBO Case Outputs'!S90/1000 -> 614.46126 | AE59: ='NBO Case Outputs'!T90/1000 -> 613.51087 | ... BQ59: ='NBO Case Outputs'!BF90/1000 -> 0
P60: Vermio South | Q60: GR_W2 | R60: GWh | S60: =SUM(X60:BQ60) -> 2309.0609 | X60: ='NBO Case Outputs'!M92/1000 -> 48.551014 | Y60: ='NBO Case Outputs'!N92/1000 -> 75.54014 | Z60: ='NBO Case Outputs'!O92/1000 -> 76.819752 | AA60: ='NBO Case Outputs'!P92/1000 -> 77.297964 | AB60: ='NBO Case Outputs'!Q92/1000 -> 77.76759 | AC60: ='NBO Case Outputs'!R92/1000 -> 78.333173 | AD60: ='NBO Case Outputs'!S92/1000 -> 78.219005 | AE60: ='NBO Case Outputs'!T92/1000 -> 78.097938 | ... BQ60: ='NBO Case Outputs'!BF92/1000 -> 0
P61: Mesokorfi | Q61: GR_W3 | R61: GWh | S61: =SUM(X61:BQ61) -> 2124.5416 | X61: ='NBO Case Outputs'!M94/1000 -> 44.310003 | Y61: ='NBO Case Outputs'!N94/1000 -> 69.490303 | Z61: ='NBO Case Outputs'!O94/1000 -> 70.673387 | AA61: ='NBO Case Outputs'!P94/1000 -> 71.114002 | AB61: ='NBO Case Outputs'!Q94/1000 -> 71.545388 | AC61: ='NBO Case Outputs'!R94/1000 -> 72.065718 | AD61: ='NBO Case Outputs'!S94/1000 -> 71.96136 | AE61: ='NBO Case Outputs'!T94/1000 -> 71.849304 | ... BQ61: ='NBO Case Outputs'!BF94/1000 -> 0
P62: Koukouras | Q62: GR_W4 | R62: GWh | S62: =SUM(X62:BQ62) -> 3043.3005 | X62: ='NBO Case Outputs'!M96/1000 -> 0 | Y62: ='NBO Case Outputs'!N96/1000 -> 0 | Z62: ='NBO Case Outputs'!O96/1000 -> 48.613544 | AA62: ='NBO Case Outputs'!P96/1000 -> 102.17548 | AB62: ='NBO Case Outputs'!Q96/1000 -> 103.33012 | AC62: ='NBO Case Outputs'!R96/1000 -> 104.08161 | AD62: ='NBO Case Outputs'!S96/1000 -> 103.9269 | AE62: ='NBO Case Outputs'!T96/1000 -> 103.76905 | ... BQ62: ='NBO Case Outputs'!BF96/1000 -> 0
P63: Panachaiko III | Q63: GR_W5 | R63: GWh | S63: =SUM(X63:BQ63) -> 1374.8366 | X63: ='NBO Case Outputs'!M98/1000 -> 0 | Y63: ='NBO Case Outputs'!N98/1000 -> 0 | Z63: ='NBO Case Outputs'!O98/1000 -> 18.922014 | AA63: ='NBO Case Outputs'!P98/1000 -> 39.739233 | AB63: ='NBO Case Outputs'!Q98/1000 -> 39.844129 | AC63: ='NBO Case Outputs'!R98/1000 -> 39.884173 | AD63: ='NBO Case Outputs'!S98/1000 -> 39.944881 | AE63: ='NBO Case Outputs'!T98/1000 -> 39.844249 | ... BQ63: ='NBO Case Outputs'!BF98/1000 -> 0
P64: Total production | R64: GWh | S64: =SUM(X64:BQ64) -> 26986.096 | X64: =SUM(X59:X63) -> 406.81833 | Y64: =SUM(Y59:Y63) -> 738.43785 | Z64: =SUM(Z59:Z63) -> 818.49858 | AA64: =SUM(AA59:AA63) -> 897.55256 | AB64: =SUM(AB59:AB63) -> 903.403 | AC64: =SUM(AC59:AC63) -> 909.72347 | AD64: =SUM(AD59:AD63) -> 908.51341 | AE64: =SUM(AE59:AE63) -> 907.07142 | ... BQ64: =SUM(BQ59:BQ63) -> 0
C78: =+MAX($B$10:C77)+0.1 -> 2.2 | D78: Revenues
P80: Vermio North | Q80: GR_W1 | R80: €m | S80: =SUM(X80:BQ80) -> 670.57986 | X80: ='NBO Case Outputs'!M161/1000 -> 14.482031 | Y80: ='NBO Case Outputs'!N161/1000 -> 43.912148 | Z80: ='NBO Case Outputs'!O161/1000 -> 44.656771 | AA80: ='NBO Case Outputs'!P161/1000 -> 44.934715 | AB80: ='NBO Case Outputs'!Q161/1000 -> 45.207767 | AC80: ='NBO Case Outputs'!R161/1000 -> 45.536551 | AD80: ='NBO Case Outputs'!S161/1000 -> 45.470133 | AE80: ='NBO Case Outputs'!T161/1000 -> 45.399805 | ... BQ80: ='NBO Case Outputs'!BF161/1000 -> 0
P81: Vermio South | Q81: GR_W2 | R81: €m | S81: =SUM(X81:BQ81) -> 85.361061 | X81: ='NBO Case Outputs'!M169/1000 -> 1.5574992 | Y81: ='NBO Case Outputs'!N169/1000 -> 5.4388901 | Z81: ='NBO Case Outputs'!O169/1000 -> 5.5310222 | AA81: ='NBO Case Outputs'!P169/1000 -> 5.5654534 | AB81: ='NBO Case Outputs'!Q169/1000 -> 5.5992665 | AC81: ='NBO Case Outputs'!R169/1000 -> 5.6399884 | AD81: ='NBO Case Outputs'!S169/1000 -> 5.6317684 | AE81: ='NBO Case Outputs'!T169/1000 -> 5.6230515 | ... BQ81: ='NBO Case Outputs'!BF169/1000 -> 0
P82: Mesokorfi | Q82: GR_W3 | R82: €m | S82: =SUM(X82:BQ82) -> 78.501662 | X82: ='NBO Case Outputs'!M177/1000 -> 1.4034212 | Y82: ='NBO Case Outputs'!N177/1000 -> 5.0033018 | Z82: ='NBO Case Outputs'!O177/1000 -> 5.0884838 | AA82: ='NBO Case Outputs'!P177/1000 -> 5.1202082 | AB82: ='NBO Case Outputs'!Q177/1000 -> 5.1512679 | AC82: ='NBO Case Outputs'!R177/1000 -> 5.1887317 | AD82: ='NBO Case Outputs'!S177/1000 -> 5.1812179 | AE82: ='NBO Case Outputs'!T177/1000 -> 5.1731499 | ... BQ82: ='NBO Case Outputs'!BF177/1000 -> 0
P83: Koukouras | Q83: GR_W4 | R83: €m | S83: =SUM(X83:BQ83) -> 106.79504 | X83: ='NBO Case Outputs'!M185/1000 -> 0 | Y83: ='NBO Case Outputs'!N185/1000 -> 0 | Z83: ='NBO Case Outputs'!O185/1000 -> 3.3543345 | AA83: ='NBO Case Outputs'!P185/1000 -> 7.0501083 | AB83: ='NBO Case Outputs'!Q185/1000 -> 7.1297782 | AC83: ='NBO Case Outputs'!R185/1000 -> 7.1816311 | AD83: ='NBO Case Outputs'!S185/1000 -> 7.1709564 | AE83: ='NBO Case Outputs'!T185/1000 -> 7.1600647 | ... BQ83: ='NBO Case Outputs'!BF185/1000 -> 0
P84: Panachaiko III | Q84: GR_W5 | R84: €m | S84: =SUM(X84:BQ84) -> 0 | X84: ='NBO Case Outputs'!M193/1000 -> 0 | Y84: ='NBO Case Outputs'!N193/1000 -> 0 | Z84: ='NBO Case Outputs'!O193/1000 -> 0 | AA84: ='NBO Case Outputs'!P193/1000 -> 0 | AB84: ='NBO Case Outputs'!Q193/1000 -> 0 | AC84: ='NBO Case Outputs'!R193/1000 -> 0 | AD84: ='NBO Case Outputs'!S193/1000 -> 0 | AE84: ='NBO Case Outputs'!T193/1000 -> 0 | ... BQ84: ='NBO Case Outputs'!BF193/1000 -> 0
